Workbook

Sheet Resultaten
A2: Havenontwerp Groep 1 volgens Haven DO
B3: Actieve LNG-tanks | D3: ='Invoer'!$D$3 | G3: Versie 3.1 DO (tekening 8.3)
A5: Ref | B5: Ontwerpresultaat | C5: Eenheid | D5: 2025 | E5: 2035 | F5: 2045 | G5: Betekenis
A6: R01 | B6: Containerligplaatsen vereist | C6: aantal | D6: ='Containers'!D15 | E6: ='Containers'!E15 | F6: ='Containers'!F15
A7: R02 | B7: Containerligplaatsen gepland | C7: aantal | D7: ='Containers'!D16 | E7: ='Containers'!E16 | F7: ='Containers'!F16
A8: R03 | B8: Bezetting containerkade | C8: deel | D8: ='Containers'!D17 | E8: ='Containers'!E17 | F8: ='Containers'!F17
A9: R04 | B9: Containerkade gemeten | C9: m | D9: ='Containers'!D18 | E9: ='Containers'!E18 | F9: ='Containers'!F18
A10: R05 | B10: STS-kranen gelijktijdig | C10: aantal | D10: ='Containers'!D19 | E10: ='Containers'!E19 | F10: ='Containers'!F19
A11: R06 | B11: Containerterrein nodig | C11: ha | D11: ='Containers'!D27 | E11: ='Containers'!E27 | F11: ='Containers'!F27
A12: R07 | B12: Containerterrein gemeten | C12: ha | D12: ='Containers'!D28 | E12: ='Containers'!E28 | F12: ='Containers'!F28
A13: R08 | B13: Graanterrein referentiemodel | C13: ha | D13: ='Overige terminals'!D10 | E13: ='Overige terminals'!E10 | F13: ='Overige terminals'!F10
A14: R09 | B14: RoRo terrein nodig | C14: ha | D14: ='Overige terminals'!D16 | E14: ='Overige terminals'!E16 | F14: ='Overige terminals'!F16
A15: R10 | B15: LNG-calls afgerond | C15: calls/jaar | D15: ='Overige terminals'!D19 | E15: ='Overige terminals'!E19 | F15: ='Overige terminals'!F19
A16: R11 | B16: LNG opslagmarge | C16: m3 | D16: ='Overige terminals'!D25 | E16: ='Overige terminals'!E25 | F16: ='Overige terminals'!F25
A17: R12 | B17: LNG opslagmarge bij tank uit | C17: m3 | D17: ='Overige terminals'!D27 | E17: ='Overige terminals'!E27 | F17: ='Overige terminals'!F27
A18: R13 | B18: Centrale vermogen voorbeeld | C18: MW | D18: ='Overige terminals'!D30 | E18: ='Overige terminals'!E30 | F18: ='Overige terminals'!F30
A21: Nautische maten volgens de DWG
B23: Rechte geulbreedte | C23: m | D23: ='Nautiek'!D20
B24: Breedte geulbocht | C24: m | D24: ='Nautiek'!D46
B25: Diepte hoofdgeul | C25: m MLWS | D25: ='Nautiek'!D25
B26: Diepte LNG-vaarweg | C26: m MLWS | D26: ='Nautiek'!D60
B27: Diepte RoRo-zone | C27: m MLWS | D27: ='Nautiek'!D61
B28: Buitenste draaikom | C28: m | D28: ='Nautiek'!D28
B29: Binnenste zwaaiplaats | C29: m | D29: ='Nautiek'!D45
B30: Havenmond | C30: m | D30: ='Nautiek'!D29
B31: Totale hoofdgeulas | C31: m | D31: ='Nautiek'!D31
B32: Geulas buiten de mond | C32: m | D32: ='Nautiek'!D50
B33: Straal geulbocht | C33: m | D33: ='Nautiek'!D47
B34: Binnenste kom tegen eerder criterium | D34: ='Nautiek'!D54
A36: Opslagcapaciteit en open gegevens
A37: Ref | B37: Onderdeel | C37: Eenheid | D37: 2025 | E37: 2035 | F37: 2045 | G37: Betekenis
A38: R14 | B38: Marge aparte lege-vakken | C38: TEU | D38: ='Containers'!D48 | E38: ='Containers'!E48 | F38: ='Containers'!F48 | G38: Ruwe bovengrens; gedeelde opslag nog kiezen
A39: R15 | B39: Toets totale containeropslag | C39: - | D39: ='Containers'!D41 | E39: ='Containers'!E41 | F39: ='Containers'!F41 | G39: Bruikbare grondslots ontbreken
A40: R16 | B40: Marge aangewezen RoRo-parkeervlakken | C40: auto | D40: ='Overige terminals'!D65 | E40: ='Overige terminals'!E65 | F40: ='Overige terminals'!F65 | G40: Bij 30 m2 per auto incl. rijruimte
A41: R17 | B41: Loodsvoorraad nodig naast silo’s | C41: ton | D41: ='Overige terminals'!D49 | E41: ='Overige terminals'!E49 | F41: ='Overige terminals'!F49 | G41: Bij indicatief 40 m silocilinder en 90% benutting
A42: R18 | B42: Status totale graanopslag | C42: - | D42: ='Overige terminals'!D56 | E42: ='Overige terminals'!E56 | F42: ='Overige terminals'!F56 | G42: Bruikbare loodsgegevens nog invullen
A43: R19 | B43: Actieve LNG-tanks | C43: aantal | D43: ='Overige terminals'!D74 | E43: ='Overige terminals'!E74 | F43: ='Overige terminals'!F74 | G43: Voorlopig; 4 cirkels tegenover 3 details
A44: R20 | B44: LNG-opslag bij één tank uit | C44: - | D44: ='Overige terminals'!D77 | E44: ='Overige terminals'!E77 | F44: ='Overige terminals'!F77 | G44: Bij geselecteerd aantal en voorraadbeleid
A47: Rekenbasis en gebruik
B48: Versie | D48: 3.0 DO | H48: 23 oktober 2026. Gemeten geometrie uit de aangeleverde Haven_DO.dwg.
...

Sheet Invoer
A2: Invoer
B3: Actieve LNG-tanks | D3: 3 | H3: Tekening DO 8.3: 3 tanks actief, 4e tank gestippeld als reserve (N-1-keuze). Zet 4 om de N-1-variant door te rekenen.
A5: Ref | B5: Parameter | C5: Eenheid | D5: 2025 | E5: 2035 | F5: 2045 | G5: Status | H5: Bron of motivering
A6: ct | B6: Containeroverslag | C6: TEU/jaar | D6: 1200000 | E6: 2000000 | F6: 4000000 | G6: Case | H6: [1] PPD-A p. 2
A7: bulk | B7: Graanoverslag | C7: ton/jaar | D7: 500000 | E7: 1000000 | F7: 1500000 | G7: Case | H7: [1] PPD-A p. 2
A8: roro | B8: Voertuigen | C8: auto/jaar | D8: 45000 | E8: 130000 | F8: 210000 | G8: Case | H8: [1] PPD-A p. 2
A9: lng | B9: LNG-overslag | C9: m3 LNG/jaar | D9: 4000000 | E9: 6000000 | F9: 8000000 | G9: Case | H9: [1] PPD-A p. 2
A10: days | B10: Kalenderdagen | C10: dagen/jaar | D10: 365 | E10: =$D10 | F10: =$D10 | G10: Definitie | H10: Geen schrikkeljaarcorrectie op conceptniveau
A11: avail | B11: Beschikbare ligplaatstijd | C11: deel | D11: 0.95 | E11: =$D11 | F11: =$D11 | G11: Rekenaanname | H11: 5% uitval door weer en onderhoud; gevoeligheid toetsen
A12: target | B12: Doelbezetting containerkade | C12: deel | D12: 0.65 | E12: =$D12 | F12: =$D12 | G12: Projectcriterium | H12: Planningsgrens; wachttijdmodel nog nodig
A13: ratio | B13: Aantal 20ft / aantal 40ft | C13: - | D13: 1.2 | E13: =$D13 | F13: =$D13 | G13: Case | H13: [1] Verhouding aantallen, niet verhouding TEU
A14: callC | B14: Overslag per containercall | C14: TEU/call | D14: 4500 | E14: =$D14 | F14: =$D14 | G14: Rekenaanname | H14: Zelfde callgrootte alle fasen; geen groei in scheepsafmetingen
A15: cranes | B15: Gelijktijdige STS-kranen per schip | C15: aantal | D15: 3 | E15: 4 | F15: 5 | G15: Ontwerpvoorstel | H15: 3/4/5 per schip blijft rekenaanname. Eindfase heeft 20 getekende STS-symbolen.
A16: qcrane | B16: Netto STS-productiviteit | C16: box/uur/kraan | D16: 30 | E16: =$D16 | F16: =$D16 | G16: Rekenaanname | H16: Te toetsen met operator; 20 geeft meer benodigde ligplaatsen
A17: moorC | B17: Tijd buiten containeroverslag | C17: uur/call | D17: 3 | E17: =$D17 | F17: =$D17 | G17: Rekenaanname | H17: Aan- en afmeren, checks en wisselen samen
A18: berths | B18: Geplande containerligplaatsen | C18: aantal | D18: 2 | E18: 3 | F18: 4 | G18: Ontwerpvoorstel | H18: 2/3/4 uit faseaantekeningen; vier kades in eindfase getekend.
A19: module | B19: Containerkade per ligplaats | C19: m | D19: ='Invoer'!D107 | E19: ='Invoer'!E107 | F19: ='Invoer'!F107 | G19: Gemeten DWG | H19: Gemeten invoer hieronder; gekoppeld aan de tekening van 23 oktober 2026.
A20: yard | B20: Te reserveren containerterrein | C20: ha | D20: ='Invoer'!D108 | E20: ='Invoer'!E108 | F20: ='Invoer'!F108 | G20: Gemeten DWG | H20: Gemeten invoer hieronder; gekoppeld aan de tekening van 23 oktober 2026.
A21: imp | B21: Aandeel import | C21: deel | D21: 0.5 | E21: =$D21 | F21: =$D21 | G21: Case | H21: [1] PPD-A p. 2
A22: exp | B22: Aandeel volle export | C22: deel | D22: 0.3 | E22: =$D22 | F22: =$D22 | G22: Case | H22: [1] PPD-A p. 2
A23: empty | B23: Aandeel lege export | C23: deel | D23: 0.2 | E23: =$D23 | F23: =$D23 | G23: Case | H23: [1] PPD-A p. 2
A24: dImp | B24: Verblijftijd import | C24: dagen | D24: 6 | E24: =$D24 | F24: =$D24 | G24: Case | H24: [1] PPD-A p. 2
A25: dExp | B25: Verblijftijd export | C25: dagen | D25: 4 | E25: =$D25 | F25: =$D25 | G25: Case | H25: [1] PPD-A p. 2
A26: dEmpty | B26: Verblijftijd leeg | C26: dagen | D26: 10 | E26: =$D26 | F26: =$D26 | G26: Case | H26: [1] PPD-A p. 2
A27: peak | B27: Piekfactor voorraad | C27: - | D27: 1.25 | E27: =$D27 | F27: =$D27 | G27: Rekenaanname | H27: Voor seizoens- en aankomstvariatie
A28: stack | B28: Effectieve gemiddelde stapeling | C28: TEU/slot | D28: 3 | E28: =$D28 | F28: =$D28 | G28: Rekenaanname | H28: Inclusief lagere stapeling voor bereikbaarheid
A29: util | B29: Benutting grondslots | C29: deel | D29: 0.7 | E29: =$D29 | F29: =$D29 | G29: Rekenaanname | H29: Operationele reserve
A30: slot | B30: Netto oppervlakte per TEU-slot | C30: m2 | D30: 28 | E30: =$D30 | F30: =$D30 | G30: Rekenaanname | H30: TEU-equivalent grondslot; niet box-slot
A31: support | B31: Terreinfactor containers / RoRo | C31: - | D31: 1.2 | E31: =$D31 | F31: =$D31 | G31: Rekenaanname | H31: Aanvulling voor apron, wegen en gebouwen
A32: callB | B32: Graan per scheepscall | C32: ton/call | D32: 65000 | E32: =$D32 | F32: =$D32 | G32: Rekenaanname | H32: Binnen 81.290 DWT; DWT is niet volledig laadvermogen
... A38: facB | B38: Factor graanopslagterrein | C38: - | D38: 2 | E38: =$D38 | F38: =$D38 | G38: Rekenaanname | H38: Opslag plus interne bediening, exclusief grote reserves
A39: areaB | B39: Graanterrein reservering | C39: ha | D39: ='Invoer'!D109 | E39: ='Invoer'!E109 | F39: ='Invoer'!F109 | G39: Gemeten DWG | H39: Gemeten invoer hieronder; gekoppeld aan de tekening van 23 oktober 2026.
A40: callR | B40: Voertuigen per scheepscall | C40: auto/call | D40: 6500 | E40: =$D40 | F40: =$D40 | G40: Rekenaanname | H40: Bovengrens gemiddelde referentie; gevoelig voor part-calls
A41: qR | B41: Netto RoRo-productiviteit | C41: auto/uur | D41: 150 | E41: =$D41 | F41: =$D41 | G41: Rekenaanname | H41: Te toetsen op rijploegen en rampconfiguratie
A42: moorR | B42: Overige tijd RoRo | C42: uur/call | D42: 4 | E42: =$D42 | F42: =$D42 | G42: Rekenaanname | H42: Aan/afmeren en controles
A43: dR | B43: Verblijftijd voertuigen | C43: dagen | D43: 10 | E43: =$D43 | F43: =$D43 | G43: Rekenaanname | H43: Open terrein
A44: peakR | B44: Piekfactor voertuigen | C44: - | D44: 1.3 | E44: =$D44 | F44: =$D44 | G44: Rekenaanname | H44: Voorraadvorming
A45: spaceR | B45: Parkeren en rijruimte per auto | C45: m2/auto | D45: 30 | E45: =$D45 | F45: =$D45 | G45: Rekenaanname | H45: Interne rijruimte inbegrepen
A46: areaR | B46: RoRo-terrein reservering | C46: ha | D46: ='Invoer'!D112 | E46: ='Invoer'!E112 | F46: ='Invoer'!F112 | G46: Gemeten DWG | H46: Gemeten invoer hieronder; gekoppeld aan de tekening van 23 oktober 2026.
A47: shipL | B47: Capaciteit LNG-referentie | C47: m3 | D47: 174000 | E47: =$D47 | F47: =$D47 | G47: Deel 1 | H47: [2] GASLOG GREECE; gegevens uit scheepsonderzoek
...

Sheet Nautiek
A2: Nautiek
B3: Actieve LNG-tanks | D3: ='Invoer'!$D$3
A5: Ref | B5: Breedtecomponent | C5: Factor B | D5: Meter | E5: Status | F5: Bron | H5: Voorwaarde
A6: N01 | B6: Basismanoeuvreerbaan | C6: 1.5 | D6: =C6*Invoer!D62 | F6: PIANC tab.3.4 | H6: Containerschip matig manoeuvreerbaar
A7: N02 | B7: Vaarsnelheid | C7: 0 | D7: =C7*Invoer!D62 | F7: PIANC tab.3.5(a) | H7: 6kn, slow: geen aparte snelheidsbreedte
A8: N03 | B8: Dwarswind | C8: 0.6 | D8: =C8*Invoer!D62 | F8: PIANC tab.3.5(b) | H8: Moderate15-33kn; operationele grens nog toetsen
A9: N04 | B9: Dwarsstroom | C9: 1 | D9: =C9*Invoer!D62 | F9: PIANC tab.3.5(c) | H9: Moderate0,5-1,5kn; conservatieve onbevestigde klasse
A10: N05 | B10: Langsstroom | C10: 0 | D10: =C10*Invoer!D62 | F10: PIANC tab.3.5(d) | H10: Laag <1,5kn aangenomen
A11: N06 | B11: Golven dwars / schuin achter | C11: 0.5 | D11: =C11*Invoer!D62 | F11: PIANC tab.3.5(e) | H11: Hs1-3m, richting nog vast te leggen
A12: N07 | B12: Navigatiehulpmiddelen | C12: 0 | D12: =C12*Invoer!D62 | F12: PIANC tab.3.5(f) | H12: Goede betonning, loodsen en DGPS voorzien
A13: N08 | B13: Bodemoppervlak | C13: =IF(D25/Invoer!D63>=1.5,0,0.2) | D13: =C13*Invoer!D62 | F13: PIANC tab.3.5(g) | H13: Conservatief hard/ruw; h<1,5T
A14: N09 | B14: Relatieve waterdiepte | C14: =IF(D25/Invoer!D63>=1.5,0,IF(D25/Invoer!D63>=1.25,0.1,0.2)) | D14: =C14*Invoer!D62 | F14: PIANC tab.3.5(h) | H14: 1,25 <= h/T <1,5 voor buitengeul
A15: N10 | B15: Oevermarge links | C15: 0.3 | D15: =C15*Invoer!D62 | F15: PIANC tab.3.6 | H15: Talud/ondiepte, slow; geen harde verticale oever
A16: N11 | B16: Oevermarge rechts | C16: 0.3 | D16: =C16*Invoer!D62 | F16: PIANC tab.3.6 | H16: Talud/ondiepte, slow; geen harde verticale oever
B18: Som breedtefactoren | C18: =SUM(C6:C16)
B19: Benodigde rechte buitengeul | C19: m | D19: =C18*Invoer!D62
B20: Getekende rechte geulbreedte | C20: m | D20: ='Invoer'!D93
A22: Verticale maatvoering en manoeuvreren
A24: N12 | B24: Som benodigde diepte | C24: m | D24: =SUM(Invoer!D63,Invoer!D64,Invoer!D65,Invoer!D66,Invoer!D67,Invoer!D68,Invoer!D69) | H24: Alle componenten als invoer zichtbaar
A25: N13 | B25: Getekende hoofdgeuldiepte | C25: m MLWS | D25: ='Invoer'!D101 | H25: −18,20 m als tekst in DWG; verticale datum nog controleren
A26: N14 | B26: Verhouding h/T | C26: - | D26: =D25/Invoer!D63 | H26: Controle op gekozen dieptefactor
A27: N15 | B27: Vereiste draaicirkel | C27: m | D27: =Invoer!D71*Invoer!D61 | H27: Projectcriterium, geen universele richtlijn
A28: N16 | B28: Gereserveerde draaicirkel | C28: m | D28: =Invoer!D72 | H28: Buitenste draaikom 1E6; binnenste zwaaiplaats apart hieronder
A29: N17 | B29: Havenmond | C29: m | D29: =Invoer!D73 | H29: Tussen obstakels op bodemniveau toetsen
A30: N18 | B30: Marge kanaalbreedte | C30: m | D30: =D20-D19 | H30: Geen extra veiligheidsklasse
A31: N19 | B31: Kanaallengte | C31: m | D31: ='Invoer'!D97 | H31: As 1E5; exclusief de twee damhartlijnen op dezelfde laag
A32: N20 | B32: Indicatieve vaartijd enkele reis | C32: uur | D32: =IF(COUNT(D31)=1,D31/(Invoer!D74*1852),"") | H32: Vaartijd exclusief scheiding, sleepboten en wachten
A35: Gevoeligheid bij dezelfde omstandigheden
A36: Ref | B36: Schipscenario | C36: Breedte m | D36: Basisfactor | E36: Extra factor | F36: Benodigde m | G36: Status
A37: S1 | B37: Reguliere container | C37: 48.2 | D37: 1.5 | E37: 0 | F37: =C37*($C$18-$C$6+D37+E37) | G37: =IF(F37<=$D$20,"BINNEN BREEDTE","EXTRA BREEDTE")
A38: S2 | B38: GASLOG GREECE | C38: 45.8 | D38: 1.5 | E38: 0 | F38: =C38*($C$18-$C$6+D38+E38) | G38: =IF(F38<=$D$20,"BINNEN BREEDTE","EXTRA BREEDTE")
A39: S3 | B39: KIRA OLDENDORFF | C39: 32.26 | D39: 1.8 | E39: 0 | F39: =C39*($C$18-$C$6+D39+E39) | G39: =IF(F39<=$D$20,"BINNEN BREEDTE","EXTRA BREEDTE")
A40: S4 | B40: BYD SHENZHEN | C40: 37.7 | D40: 1.5 | E40: 0.2 | F40: =C40*($C$18-$C$6+D40+E40) | G40: =IF(F40<=$D$20,"BINNEN BREEDTE","EXTRA BREEDTE")
A41: S5 | B41: MOZAH grensscenario | C41: 53.8 | D41: 1.5 | E41: 0 | F41: =C41*($C$18-$C$6+D41+E41) | G41: =IF(F41<=$D$20,"BINNEN BREEDTE","EXTRA BREEDTE")
A44: Aanvullende nautische maten uit de tekening
B45: Binnenste zwaaiplaats | C45: m | D45: ='Invoer'!D100 | H45: 1ED; afzonderlijk van buitenste draaikom
B46: Getekende bochtbreedte | C46: m | D46: ='Invoer'!D94 | H46: 40 m breder dan recht deel; nautische toets nog nodig
B47: Straal van de geulbocht | C47: m | D47: ='Invoer'!D95 | H47: Gemeten asgeometrie
B48: Richtingsverandering | C48: graden | D48: ='Invoer'!D96 | H48: Gemeten asgeometrie
B49: Stopweg binnen de havenmond | C49: m | D49: ='Invoer'!D98 | H49: Asdeel in voorhaven, niet extra bij geullengte optellen
...

Sheet Containers
A2: Containers
B3: Actieve LNG-tanks | D3: ='Invoer'!$D$3
A5: Ref | B5: Berekening | C5: Eenheid | D5: 2025 | E5: 2035 | F5: 2045 | G5: Status | H5: Toelichting
A6: C01 | B6: TEU per fysieke container | C6: TEU/box | D6: =(Invoer!D13+2)/(Invoer!D13+1) | E6: =(Invoer!E13+2)/(Invoer!E13+1) | F6: =(Invoer!F13+2)/(Invoer!F13+1) | H6: N20 = 1,2 N40; box is één fysieke container
A7: C02 | B7: Jaarlijkse kraanbewegingen | C7: box/jaar | D7: =Invoer!D6/D6 | E7: =Invoer!E6/E6 | F7: =Invoer!F6/F6 | H7: Eén kadetransfer per box; rehandles apart
A8: C03 | B8: Gemiddelde containercalls | C8: calls/jaar | D8: =Invoer!D6/Invoer!D14 | E8: =Invoer!E6/Invoer!E14 | F8: =Invoer!F6/Invoer!F14 | H8: Gemiddeld; afgeronde planning staat eronder
A9: C04 | B9: Calls afgerond naar boven | C9: calls/jaar | D9: =ROUNDUP(D8,0) | E9: =ROUNDUP(E8,0) | F9: =ROUNDUP(F8,0) | H9: Voor planning en verkeersbelasting
A10: C05 | B10: Kraanbewegingen per call | C10: box/call | D10: =Invoer!D14/D6 | E10: =Invoer!E14/E6 | F10: =Invoer!F14/F6 | H10: Parcel is kadedoorzet; geen gehele scheepscapaciteit
A11: C06 | B11: Effectieve scheepsproductiviteit | C11: box/uur | D11: =Invoer!D15*Invoer!D16 | E11: =Invoer!E15*Invoer!E16 | F11: =Invoer!F15*Invoer!F16 | H11: Netto productiviteit per kraan x gelijktijdige kranen
A12: C07 | B12: Overslag plus overige tijd | C12: uur/call | D12: =D10/D11+Invoer!D17 | E12: =E10/E11+Invoer!E17 | F12: =F10/F11+Invoer!F17 | H12: Vervangt de oude vaste aanname van 28 uur
A13: C08 | B13: Ligplaatsuren totaal | C13: uur/jaar | D13: =D9*D12 | E13: =E9*E12 | F13: =F9*F12 | H13: Afgeronde calls voor conservatieve bezetting
A14: C09 | B14: Beschikbare uren per berth | C14: uur/jaar | D14: =Invoer!D10*24*Invoer!D11 | E14: =Invoer!E10*24*Invoer!E11 | F14: =Invoer!F10*24*Invoer!F11 | H14: 5% totale berthuitval als ontwerphypothese
A15: C10 | B15: Benodigde containerligplaatsen | C15: aantal | D15: =ROUNDUP(D13/(D14*Invoer!D12),0) | E15: =ROUNDUP(E13/(E14*Invoer!E12),0) | F15: =ROUNDUP(F13/(F14*Invoer!F12),0) | H15: Toets is capaciteitsberekening, geen wachtrijbewijs
A16: C11 | B16: Geplande containerligplaatsen | C16: aantal | D16: =Invoer!D18 | E16: =Invoer!E18 | F16: =Invoer!F18 | H16: Intekenen na keuze
A17: C12 | B17: Bezetting geplande kades | C17: deel | D17: =D13/(D14*D16) | E17: =E13/(E14*E16) | F17: =F13/(F14*F16) | H17: Vergeleken met projectcriterium 65%
A18: C13 | B18: Containerkade volgens tekening | C18: m | D18: =D16*Invoer!D19 | E18: =E16*Invoer!E19 | F18: =F16*Invoer!F19 | H18: Aantal ligplaatsen x gemeten lengte van circa 401,1 m
A19: C14 | B19: STS-kranen in operatie | C19: aantal | D19: =D16*Invoer!D15 | E19: =E16*Invoer!E15 | F19: =F16*Invoer!F15 | H19: Gelijktijdig bij volledige bezetting; geen onderhoudsreserve
A20: C15 | B20: Gewogen verblijftijd | C20: dagen | D20: =Invoer!D21*Invoer!D24+Invoer!D22*Invoer!D25+Invoer!D23*Invoer!D26 | E20: =Invoer!E21*Invoer!E24+Invoer!E22*Invoer!E25+Invoer!E23*Invoer!E26 | F20: =Invoer!F21*Invoer!F24+Invoer!F22*Invoer!F25+Invoer!F23*Invoer!F26 | H20: 6,2 dagen volgens case
A21: C16 | B21: Piekvoorraad import | C21: TEU | D21: =Invoer!D6*Invoer!D21*Invoer!D24/Invoer!D10*Invoer!D27 | E21: =Invoer!E6*Invoer!E21*Invoer!E24/Invoer!E10*Invoer!E27 | F21: =Invoer!F6*Invoer!F21*Invoer!F24/Invoer!F10*Invoer!F27 | H21: TEU-dagen; geen extra conversie naar box
A22: C17 | B22: Piekvoorraad volle export | C22: TEU | D22: =Invoer!D6*Invoer!D22*Invoer!D25/Invoer!D10*Invoer!D27 | E22: =Invoer!E6*Invoer!E22*Invoer!E25/Invoer!E10*Invoer!E27 | F22: =Invoer!F6*Invoer!F22*Invoer!F25/Invoer!F10*Invoer!F27
A23: C18 | B23: Piekvoorraad lege export | C23: TEU | D23: =Invoer!D6*Invoer!D23*Invoer!D26/Invoer!D10*Invoer!D27 | E23: =Invoer!E6*Invoer!E23*Invoer!E26/Invoer!E10*Invoer!E27 | F23: =Invoer!F6*Invoer!F23*Invoer!F26/Invoer!F10*Invoer!F27
A24: C19 | B24: Piekvoorraad totaal | C24: TEU | D24: =SUM(D21:D23) | E24: =SUM(E21:E23) | F24: =SUM(F21:F23) | H24: Som van drie stromen
A25: C20 | B25: Benodigde TEU-grondslots | C25: slots | D25: =D24/(Invoer!D28*Invoer!D29) | E25: =E24/(Invoer!E28*Invoer!E29) | F25: =F24/(Invoer!F28*Invoer!F29) | H25: 3 hoog bij 70% slotbenutting
A26: C21 | B26: Netto opslagoppervlakte | C26: ha | D26: =D25*Invoer!D30/10000 | E26: =E25*Invoer!E30/10000 | F26: =F25*Invoer!F30/10000 | H26: 28 m2 per TEU-grondslot
A27: C22 | B27: Containerterminal totaal | C27: ha | D27: =D26*Invoer!D31 | E27: =E26*Invoer!E31 | F27: =F26*Invoer!F31 | H27: Netto opslag x 1,2; equipmentindeling toetsen
A28: C23 | B28: Containerterrein volgens tekening | C28: ha | D28: =Invoer!D20 | E28: =Invoer!E20 | F28: =Invoer!F20 | H28: Cumulatief gemeten fasevlakken uit de DWG
A29: C24 | B29: Marge terrein | C29: ha | D29: =D28-D27 | E29: =E28-E27 | F29: =F28-F27 | H29: Alleen terreinmodel; bruikbare opslagvakken hieronder nog toetsen
A30: C25 | B30: Capaciteitstoets kades | C30: - | D30: =IF(D15<=D16,"VOLDOET REKENKUNDIG","MEER CAPACITEIT NODIG") | E30: =IF(E15<=E16,"VOLDOET REKENKUNDIG","MEER CAPACITEIT NODIG") | F30: =IF(F15<=F16,"VOLDOET REKENKUNDIG","MEER CAPACITEIT NODIG") | H30: Geen garantie voor korte wachttijden
A32: Getekende opslagvakken en bruikbare slots
A33: Ref | B33: Berekening | C33: Eenheid | D33: 2025 | E33: 2035 | F33: 2045 | G33: Status | H33: Toelichting
A34: C26 | B34: Reguliere stackvakken | C34: m2 | D34: ='Invoer'!D119 | E34: ='Invoer'!E119 | F34: ='Invoer'!F119 | H34: Werkelijke oppervlakte binnen de cumulatieve fasegrens
A35: C27 | B35: Reefervakken | C35: m2 | D35: ='Invoer'!D120 | E35: ='Invoer'!E120 | F35: ='Invoer'!F120 | H35: Benodigd reeferaandeel en aansluitingen nog niet gegeven
A36: C28 | B36: Aparte vakken lege containers | C36: m2 | D36: ='Invoer'!D121 | E36: ='Invoer'!E121 | F36: ='Invoer'!F121 | H36: In fase 1 en 2 zijn geen aparte lege-vakken getekend
A37: C29 | B37: Oppervlakte alle opslagblokken | C37: m2 | D37: =SUM(D34:D36) | E37: =SUM(E34:E36) | F37: =SUM(F34:F36) | H37: Geen slotcapaciteit uit alleen oppervlakte afleiden
A38: C30 | B38: Bruikbare grondslots totaal | C38: slots | D38: =IF(COUNT('Invoer'!D122)=1,'Invoer'!D122,"n.a.") | E38: =IF(COUNT('Invoer'!E122)=1,'Invoer'!E122,"n.a.") | F38: =IF(COUNT('Invoer'!F122)=1,'Invoer'!F122,"n.a.") | H38: Nog te tellen in de vakindeling
A39: C31 | B39: Voorraadcapaciteit uit slots | C39: TEU | D39: =IF(COUNT(D38)=1,D38*'Invoer'!D28*'Invoer'!D29,"n.a.") | E39: =IF(COUNT(E38)=1,E38*'Invoer'!E28*'Invoer'!E29,"n.a.") | F39: =IF(COUNT(F38)=1,F38*'Invoer'!F28*'Invoer'!F29,"n.a.") | H39: Slots x gemiddelde lagen x operationele benutting
A40: C32 | B40: Marge voorraadcapaciteit | C40: TEU | D40: =IF(COUNT(D39)=1,D39-D24,"n.a.") | E40: =IF(COUNT(E39)=1,E39-E24,"n.a.") | F40: =IF(COUNT(F39)=1,F39-F24,"n.a.") | H40: Positief vereist; geen extra terreinreservering bijtellen
A41: C33 | B41: Toets werkelijke opslagcapaciteit | C41: - | D41: =IF(COUNT(D40)=1,IF(D40>=0,"VOLDOET REKENKUNDIG","OPSLAGTEKORT"),"GRONDSLOTS INVULLEN") | E41: =IF(COUNT(E40)=1,IF(E40>=0,"VOLDOET REKENKUNDIG","OPSLAGTEKORT"),"GRONDSLOTS INVULLEN") | F41: =IF(COUNT(F40)=1,IF(F40>=0,"VOLDOET REKENKUNDIG","OPSLAGTEKORT"),"GRONDSLOTS INVULLEN") | H41: Terreintoets en slottoets zijn verschillende controles
A42: C34 | B42: Benodigde slots lege containers | C42: slots | D42: =ROUNDUP(D23/('Invoer'!D28*'Invoer'!D29),0) | E42: =ROUNDUP(E23/('Invoer'!E28*'Invoer'!E29),0) | F42: =ROUNDUP(F23/('Invoer'!F28*'Invoer'!F29),0) | H42: Volgt uit dezelfde lege voorraad; benodigde hele slots naar boven afgerond
A43: C35 | B43: Toegewezen bruikbare lege-slots | C43: slots | D43: =IF(COUNT('Invoer'!D123)=1,'Invoer'!D123,"n.a.") | E43: =IF(COUNT('Invoer'!E123)=1,'Invoer'!E123,"n.a.") | F43: =IF(COUNT('Invoer'!F123)=1,'Invoer'!F123,"n.a.") | H43: Ook gedeelde reguliere vakken kunnen worden toegewezen
...

Sheet Overige terminals
A2: Overige terminals
B3: Actieve LNG-tanks | D3: ='Invoer'!$D$3
A5: Ref | B5: Berekening | C5: Eenheid | D5: 2025 | E5: 2035 | F5: 2045 | G5: Status | H5: Toelichting
A6: T01 | B6: Graancalls afgerond | C6: calls/jaar | D6: =ROUNDUP(Invoer!D7/Invoer!D32,0) | E6: =ROUNDUP(Invoer!E7/Invoer!E32,0) | F6: =ROUNDUP(Invoer!F7/Invoer!F32,0) | H6: 65000 ton per call als conceptparcel
A7: T02 | B7: Graan ligplaatstijd | C7: uur/call | D7: =Invoer!D32/Invoer!D33+Invoer!D34 | E7: =Invoer!E32/Invoer!E33+Invoer!E34 | F7: =Invoer!F32/Invoer!F33+Invoer!F34 | H7: Bij constante netto beladerproductiviteit
A8: T03 | B8: Bezetting één graanligplaats | C8: deel | D8: =D6*D7/(Invoer!D10*24*Invoer!D11) | E8: =E6*E7/(Invoer!E10*24*Invoer!E11) | F8: =F6*F7/(Invoer!F10*24*Invoer!F11) | H8: Piekcampagnes apart toetsen
A9: T04 | B9: Graan piekvoorraad | C9: ton | D9: =Invoer!D7*Invoer!D35/Invoer!D10*Invoer!D27 | E9: =Invoer!E7*Invoer!E35/Invoer!E10*Invoer!E27 | F9: =Invoer!F7*Invoer!F35/Invoer!F10*Invoer!F27 | H9: 30 dagen met piekfactor 1,25
A10: T05 | B10: Graanterreinbehoefte referentiemodel | C10: ha | D10: =D9/Invoer!D36/Invoer!D37*Invoer!D38/10000 | E10: =E9/Invoer!E36/Invoer!E37*Invoer!E38/10000 | F10: =F9/Invoer!F36/Invoer!F37*Invoer!F38/10000 | H10: Oud 8 m terreinmodel; silo’s en loods worden hieronder afzonderlijk beoordeeld.
A11: T06 | B11: Graanterrein reservering | C11: ha | D11: =Invoer!D39 | E11: =Invoer!E39 | F11: =Invoer!F39 | H11: Gemeten 30,42 ha hoofdperceel; opslagdeel niet extra optellen
A12: T07 | B12: RoRo calls afgerond | C12: calls/jaar | D12: =ROUNDUP(Invoer!D8/Invoer!D40,0) | E12: =ROUNDUP(Invoer!E8/Invoer!E40,0) | F12: =ROUNDUP(Invoer!F8/Invoer!F40,0) | H12: 6500 auto/call; lagere parcel geeft meer calls
A13: T08 | B13: RoRo ligplaatstijd | C13: uur/call | D13: =Invoer!D40/Invoer!D41+Invoer!D42 | E13: =Invoer!E40/Invoer!E41+Invoer!E42 | F13: =Invoer!F40/Invoer!F41+Invoer!F42 | H13: Netto150 auto/uur als hypothese
A14: T09 | B14: Bezetting één RoRo-ligplaats | C14: deel | D14: =D12*D13/(Invoer!D10*24*Invoer!D11) | E14: =E12*E13/(Invoer!E10*24*Invoer!E11) | F14: =F12*F13/(Invoer!F10*24*Invoer!F11) | H14: Rampconflicten nog toetsen
A15: T10 | B15: RoRo piekvoorraad | C15: auto | D15: =Invoer!D8*Invoer!D43/Invoer!D10*Invoer!D44 | E15: =Invoer!E8*Invoer!E43/Invoer!E10*Invoer!E44 | F15: =Invoer!F8*Invoer!F43/Invoer!F10*Invoer!F44
A16: T11 | B16: RoRo oppervlakte totaal | C16: ha | D16: =D15*Invoer!D45*Invoer!D31/10000 | E16: =E15*Invoer!E45*Invoer!E31/10000 | F16: =F15*Invoer!F45*Invoer!F31/10000 | H16: 30m2 inclusief rijruimte, 20% extra support
A17: T12 | B17: RoRo terrein reservering | C17: ha | D17: =Invoer!D46 | E17: =Invoer!E46 | F17: =Invoer!F46 | H17: Gemeten 30,21 ha; toegewezen parkeervlakken apart toetsen
A18: T13 | B18: LNG effectieve scheepslading | C18: m3/call | D18: =Invoer!D47*Invoer!D48 | E18: =Invoer!E47*Invoer!E48 | F18: =Invoer!F47*Invoer!F48 | H18: Reguliere vloot; geen MOZAH
A19: T14 | B19: LNG calls afgerond | C19: calls/jaar | D19: =ROUNDUP(Invoer!D9/D18,0) | E19: =ROUNDUP(Invoer!E9/E18,0) | F19: =ROUNDUP(Invoer!F9/F18,0) | H19: Afgeronde calls voor berthbezetting
A20: T15 | B20: LNG ligplaatstijd | C20: uur/call | D20: =D18/Invoer!D49+Invoer!D50 | E20: =E18/Invoer!E49+Invoer!E50 | F20: =F18/Invoer!F49+Invoer!F50 | H20: 10000m3/uur + 8 uur overige tijd
A21: T16 | B21: Bezetting één LNG-steiger | C21: deel | D21: =D19*D20/(Invoer!D10*24*Invoer!D11) | E21: =E19*E20/(Invoer!E10*24*Invoer!E11) | F21: =F19*F20/(Invoer!F10*24*Invoer!F11) | H21: Geen LNG-operability of QRA-bewijs
A22: T17 | B22: Nominale LNG-opslag | C22: m3 | D22: =Invoer!D51*Invoer!D52 | E22: =Invoer!E51*Invoer!E52 | F22: =Invoer!F51*Invoer!F52 | H22: Actieve tankkeuze in Invoer D3; aantal nog te bevestigen
A23: T18 | B23: Operationele opslagband | C23: m3 | D23: =D22*(Invoer!D54-Invoer!D53) | E23: =E22*(Invoer!E54-Invoer!E53) | F23: =F22*(Invoer!F54-Invoer!F53) | H23: Tussen 10% en90% vulling, totaal80% nominaal
A24: T19 | B24: Buffer plus ontvangstruimte | C24: m3 | D24: =Invoer!D9/Invoer!D10*Invoer!D55+D18 | E24: =Invoer!E9/Invoer!E10*Invoer!E55+E18 | F24: =Invoer!F9/Invoer!F10*Invoer!F55+F18 | H24: 7 dagen gemiddelde vraag + volledige scheepsparcel
A25: T20 | B25: Opslagmarge | C25: m3 | D25: =D23-D24 | E25: =E23-E24 | F25: =F23-F24 | H25: Positief vereist onder gekozen voorraadbeleid
A26: T21 | B26: Opslagband bij één tank uit | C26: m3 | D26: =MAX(0,Invoer!D51-1)*Invoer!D52*(Invoer!D54-Invoer!D53) | E26: =MAX(0,Invoer!E51-1)*Invoer!E52*(Invoer!E54-Invoer!E53) | F26: =MAX(0,Invoer!F51-1)*Invoer!F52*(Invoer!F54-Invoer!F53) | H26: N-1 toets; operationele eis nog te kiezen
A27: T22 | B27: Marge bij één tank uit | C27: m3 | D27: =D26-D24 | E27: =E26-E24 | F27: =F26-F24 | H27: Negatief vraagt lager bufferbeleid of extra tank
A28: T23 | B28: Gas naar regionaal systeem | C28: Nm3/jaar | D28: =Invoer!D9*Invoer!D56 | E28: =Invoer!E9*Invoer!E56 | F28: =Invoer!F9*Invoer!F56 | H28: Inclusief gas richting centrale; geen extra gasproductie
A29: T24 | B29: Elektriciteitsproductie voorbeeld | C29: MWh/jaar | D29: =Invoer!D9*Invoer!D57*Invoer!D58*Invoer!D59 | E29: =Invoer!E9*Invoer!E57*Invoer!E58*Invoer!E59 | F29: =Invoer!F9*Invoer!F57*Invoer!F58*Invoer!F59 | H29: 50% LNG naar centrale, rendement60% als rekenvoorbeeld
A30: T25 | B30: Centrale eindcapaciteit voorbeeld | C30: MW | D30: =Invoer!F9*Invoer!F57*Invoer!F58*Invoer!F59/(Invoer!F10*24*Invoer!F60) | E30: =Invoer!F9*Invoer!F57*Invoer!F58*Invoer!F59/(Invoer!F10*24*Invoer!F60) | F30: =Invoer!F9*Invoer!F57*Invoer!F58*Invoer!F59/(Invoer!F10*24*Invoer!F60) | H30: Oppervlakte centrale gemeten; 50% LNG-toedeling blijft rekenvoorbeeld
A33: Verkeer voor hoofdgeul en verkeersplanning
B35: Aanlopen alle ladingstromen | C35: calls/jaar | D35: =Containers!D9+D6+D12+D19 | E35: =Containers!E9+E6+E12+E19 | F35: =Containers!F9+F6+F12+F19
B36: Aankomst plus vertrek | C36: bewegingen/jaar | D36: =2*D35 | E36: =2*E35 | F36: =2*F35
B37: Gemiddelde geulbewegingen | C37: per dag | D37: =D36/Invoer!D10 | E37: =E36/Invoer!E10 | F37: =F36/Invoer!F10
A40: Graan indicatief opslagmodel bij de aangegeven silohoogte
A41: Ref | B41: Berekening | C41: Eenheid | D41: 2025 | E41: 2035 | F41: 2045 | G41: Status | H41: Toelichting
A42: T26 | B42: Aantal silo’s | C42: aantal | D42: ='Invoer'!D125 | E42: ='Invoer'!E125 | F42: ='Invoer'!F125 | H42: Geteld in tekening
A43: T27 | B43: Nominale diameter | C43: m | D43: ='Invoer'!D126 | E43: ='Invoer'!E126 | F43: ='Invoer'!F126 | H43: Nominale 30 m uit de aantekening
A44: T28 | B44: Aangegeven hoogte | C44: m | D44: ='Invoer'!D127 | E44: ='Invoer'!E127 | F44: ='Invoer'!F127 | H44: Nog niet als volledige bruikbare cilinderhoogte bevestigd
A45: T29 | B45: Bruto cilindervolume silo’s | C45: m3 | D45: =D42*PI()*D43^2/4*D44 | E45: =E42*PI()*E43^2/4*E44 | F45: =F42*PI()*F43^2/4*F44 | H45: Geometrisch scenario; constructiehoogte kan afwijken van opslaghoogte
A46: T30 | B46: Bruto massa in silocilinders | C46: ton | D46: =D45*'Invoer'!D36 | E46: =E45*'Invoer'!E36 | F46: =F45*'Invoer'!F36 | H46: Graandichtheid uit bestaande invoer
A47: T31 | B47: Indicatieve massa bij gekozen vulfactor | C47: ton | D47: =D46*'Invoer'!D128 | E47: =E46*'Invoer'!E128 | F47: =F46*'Invoer'!F128 | H47: Bij 40 m cilinder en 90% benutting; geen leverancierscapaciteit
...

Sheet Grondwerk
A2: Grondwerk
B3: Actieve LNG-tanks | D3: ='Invoer'!$D$3
A5: Zone | B5: Baggervak | C5: Oppervlakte m2 | D5: Bestaande diepte m | E5: Ontwerpdiepte m | F5: Volume m3 | G5: Status | H5: Geometrie en beperking
A6: G1 | B6: Buitengeul (tot geuleinde) | C6: 4558615.2 | D6: 13.97 | E6: ='Invoer'!D101 | F6: =IF(COUNT(C6:E6)=3,C6*MAX(0,E6-D6),"") | G6: =IF(COUNT(C6,E6)<2,"CONTOUR OF DIEPTE KIEZEN",IF(COUNT(D6)<1,"BODEMGEGEVENS ONTBREKEN","VOORLOPIGE SCHATTING")) | H6: Bodemmodel: zone 2 (tot DHN -15, 17,25 km) 3,90 km2 gem. 13,51 m; zone 3 0,66 km2 gem. 16,71 m
A7: G2 | B7: Voorhaven en buitenste draaikom | C7: 902302.78 | D7: 0.75 | E7: ='Invoer'!D101 | F7: =IF(COUNT(C7:E7)=3,C7*MAX(0,E7-D7),"") | G7: =IF(COUNT(C7,E7)<2,"CONTOUR OF DIEPTE KIEZEN",IF(COUNT(D7)<1,"BODEMGEGEVENS ONTBREKEN","VOORLOPIGE SCHATTING")) | H7: Bodemmodel: gem. 0,75 m diep (strand en strandwal deels boven MLWS)
A8: G3 | B8: Hoofdbekken + zwaaiplaats netto | C8: ='Invoer'!D146-'Invoer'!D147 | D8: -6.89 | E8: ='Invoer'!D101 | F8: =IF(COUNT(C8:E8)=3,C8*MAX(0,E8-D8),"") | G8: =IF(COUNT(C8,E8)<2,"CONTOUR OF DIEPTE KIEZEN",IF(COUNT(D8)<1,"BODEMGEGEVENS ONTBREKEN","VOORLOPIGE SCHATTING")) | H8: Negatief = land boven MLWS (ontgraven); DEM incl. begroeiing
A9: G4 | B9: LNG-vaarweg | C9: 379594.82 | D9: 2.48 | E9: ='Invoer'!D102 | F9: =IF(COUNT(C9:E9)=3,C9*MAX(0,E9-D9),"") | G9: =IF(COUNT(C9,E9)<2,"CONTOUR OF DIEPTE KIEZEN",IF(COUNT(D9)<1,"BODEMGEGEVENS ONTBREKEN","VOORLOPIGE SCHATTING")) | H9: Bodemmodel: gem. 2,48 m diep
A10: G5 | B10: Insteek F2 | C10: 222247.6 | D10: -5.94 | E10: ='Invoer'!D101 | F10: =IF(COUNT(C10:E10)=3,C10*MAX(0,E10-D10),"") | G10: =IF(COUNT(C10,E10)<2,"CONTOUR OF DIEPTE KIEZEN",IF(COUNT(D10)<1,"BODEMGEGEVENS ONTBREKEN","VOORLOPIGE SCHATTING")) | H10: Land, gem. +5,94 m
A11: G6 | B11: Insteek F3 | C11: 230404.4 | D11: -6.5 | E11: ='Invoer'!D101 | F11: =IF(COUNT(C11:E11)=3,C11*MAX(0,E11-D11),"") | G11: =IF(COUNT(C11,E11)<2,"CONTOUR OF DIEPTE KIEZEN",IF(COUNT(D11)<1,"BODEMGEGEVENS ONTBREKEN","VOORLOPIGE SCHATTING")) | H11: Land, gem. +6,50 m
A12: G7 | B12: RoRo-ligplaatsvak | C12: 22355.67 | D12: -6.47 | E12: ='Invoer'!D103 | F12: =IF(COUNT(C12:E12)=3,C12*MAX(0,E12-D12),"") | G12: =IF(COUNT(C12,E12)<2,"CONTOUR OF DIEPTE KIEZEN",IF(COUNT(D12)<1,"BODEMGEGEVENS ONTBREKEN","VOORLOPIGE SCHATTING")) | H12: Tegen de RoRo-kade (v8.3); land, gem. +6,47 m
A13: G8 | B13: Reserve insteek 2 (na 2045) | C13: 0 | D13: -7.84 | E13: ='Invoer'!D101 | F13: =IF(COUNT(C13:E13)=3,C13*MAX(0,E13-D13),"") | G13: =IF(COUNT(C13,E13)<2,"CONTOUR OF DIEPTE KIEZEN",IF(COUNT(D13)<1,"BODEMGEGEVENS ONTBREKEN","VOORLOPIGE SCHATTING")) | H13: Niet baggeren t/m 2045 (666.139 m2 gereserveerd; later ca. 17,3 mln m3)
A14: G9 | B14: Insteek F1 (containers) | C14: 472389 | D14: -6.99 | E14: ='Invoer'!D101 | F14: =IF(COUNT(C14:E14)=3,C14*MAX(0,E14-D14),"") | G14: =IF(COUNT(C14,E14)<2,"CONTOUR OF DIEPTE KIEZEN",IF(COUNT(D14)<1,"BODEMGEGEVENS ONTBREKEN","VOORLOPIGE SCHATTING")) | H14: Was open lijn 1EE; nu gesloten vak F1 (v8.3); land, gem. +6,99 m
A15: G10 | B15: Reserve hoofdbekken (na 2045) | C15: 0 | D15: -6.2 | E15: ='Invoer'!D101 | F15: =IF(COUNT(C15:E15)=3,C15*MAX(0,E15-D15),"") | G15: =IF(COUNT(C15,E15)<2,"CONTOUR OF DIEPTE KIEZEN",IF(COUNT(D15)<1,"BODEMGEGEVENS ONTBREKEN","VOORLOPIGE SCHATTING")) | H15: Niet baggeren t/m 2045 (555.166 m2 gereserveerd; later ca. 13,5 mln m3)
B17: Totaal baggervolume volledig model | F17: =IF(COUNT(F6:F15)=10,SUM(F6:F15),"") | G17: =IF(COUNT(F6:F15)=10,"VOORLOPIGE SCHATTING","GEEN VOLLEDIG VOLUME")
B18: Som bekende deeloppervlakken | C18: =SUM(C6:C15) | H18: Dit is geen complete havenoppervlakte zolang de resterende contouren en overlap niet zijn vastgesteld.
A21: Bodemprofielen uit de cursus
A22: Ref | B22: Gebied | C22: Zand | D22: Zachte klei | E22: Stevig/hard | F22: Som | G22: Toets | H22: Gebruik
A23: 1 | B23: Havenbekken | C23: 0.2 | D23: 0.3 | E23: 0.5 | F23: =SUM(C23:E23) | G23: =IF(ABS(F23-1)<0.000001,"100%","CONTROLEER") | H23: Geul bij DHN -15 eerst splitsen; gemengd materiaal niet voor reclamatie.
A24: 2 | B24: Geul tot DHN -15 | C24: 0.5 | D24: 0.15 | E24: 0.35 | F24: =SUM(C24:E24) | G24: =IF(ABS(F24-1)<0.000001,"100%","CONTROLEER") | H24: Geul bij DHN -15 eerst splitsen; gemengd materiaal niet voor reclamatie.
A25: 3 | B25: Geul voorbij DHN -15 | C25: 0.5 | D25: 0.3 | E25: 0.2 | F25: =SUM(C25:E25) | G25: =IF(ABS(F25-1)<0.000001,"100%","CONTROLEER") | H25: Geul bij DHN -15 eerst splitsen; gemengd materiaal niet voor reclamatie.
B27: Verticaal datum | H27: Alle diepten positief naar beneden en in hetzelfde datum. Bestaande bodem of TIN ontbreekt; MSL-MLWS verschil nog onderbouwen.
A32: Reclamatie uit unieke vlakken en hoogten
A33: Ref | B33: Onderdeel | C33: Eenheid | D33: Waarde | E33: Status | F33: Toelichting
A34: G11 | B34: Te vullen oppervlakte | C34: m2 | D34: 3459600 | F34: Terminals, LNG, centrale, havendienst (DO 8.3)
A35: G12 | B35: Bestaande gemiddelde hoogte | C35: m zelfde datum | D35: 7.06 | F35: Copernicus DEM (oppervlak incl. begroeiing) t.o.v. MLWS; werkelijk maaiveld lager
A36: G13 | B36: Ontwerp bovenzijde | C36: m zelfde datum | D36: 5 | F36: Aanname terreinhoogte +5,0 m MLWS
A37: G14 | B37: Extra laag voor zetting | C37: m | D37: 0.5 | F37: Aanname zetting
B39: Vulvolume schatting | C39: m3 | D39: =IF(COUNT(D34:D37)=4,D34*MAX(0,D36-D35+D37),"") | E39: =IF(COUNT(D34:D37)=4,"SCHATTING","INVOER ONTBREEKT") | F39: Gemiddeld geen ophoging: terrein ligt hoger dan +5,0 m. Celmethode: ophogen 0,36 mln m3, afgraven 7,35 mln m3
B42: Geen som van alle terminalvlakken | H42: Ophoogterrein is niet gelijk aan alle percelen samen. Bestaand land, binnenvlakken en overlap eerst onderscheiden.

Sheet Afweging
A2: Afweging
B3: Actieve LNG-tanks | D3: ='Invoer'!$D$3
A5: Ref | B5: Criterium | C5: Gewicht | D5: A lineair | E5: B referentie | F5: C offshore | G5: D gescheiden | H5: Bewijs nodig
A6: M1 | B6: Bevaarbaarheid | C6: 0.3 | H6: Simulatie, toegangsroute en vrije draaicirkel
A7: M2 | B7: Baggeren en reclameren | C7: 0.25 | H7: Geometrie, bathymetrie, grondsoort en volume
A8: M3 | B8: Complexiteit aanleg | C8: 0.2 | H8: Dammen, funderingen, uitvoeringsvolgorde
A9: M4 | B9: Fasering en uitbreidbaarheid | C9: 0.15 | H9: Bouwen tijdens exploitatie en grondreserveringen
A10: M5 | B10: Milieu en LNG-scheiding | C10: 0.1 | H10: Ecologie, baggerstort, QRA en koelwater
B12: Som gewichten | C12: =SUM(C6:C10)
B14: Gewogen score 1 tot 5 | D14: =IF(AND(COUNT(D6:D10)=5,ABS($C$12-1)<0.000001),SUMPRODUCT($C$6:$C$10,D6:D10),"") | E14: =IF(AND(COUNT(E6:E10)=5,ABS($C$12-1)<0.000001),SUMPRODUCT($C$6:$C$10,E6:E10),"") | F14: =IF(AND(COUNT(F6:F10)=5,ABS($C$12-1)<0.000001),SUMPRODUCT($C$6:$C$10,F6:F10),"") | G14: =IF(AND(COUNT(G6:G10)=5,ABS($C$12-1)<0.000001),SUMPRODUCT($C$6:$C$10,G6:G10),"")
B16: Huidige voorkeursrichting | D16: Porto Central als vormreferentie
B18: Status vergelijking | D18: =IF(COUNT(D14:G14)=4,"VOLLEDIG INGEVOERD","GROEPSSCHETSEN EN SCORES NODIG")
H20: Vul alleen scores in met motivering. 1 ongunstig, 5 gunstig. De oude 4,35-score geldt niet voor dit ontwerp.

Sheet Keuzes
A2: Keuzes
B3: Actieve LNG-tanks | D3: ='Invoer'!$D$3
A5: Ref | B5: Onderwerp | C5: Besluit of voorstel | D5: Status | E5: Onderbouwing
A6: K01 | B6: Groep 1 programma | C6: Containers, graan, voertuigen, LNG en centrale | D6: Opdracht | E6: [1]
A7: K02 | B7: Havenvorm | C7: Porto Central als referentie voor bekken, vingers en golfbrekers | D7: Gebruikerskeuze | E7: Beelden gebruiker + [6]
A8: K03 | B8: Tekenwerk | C8: Gebruiker maakt eigen tekeningen | D8: Gebruikerskeuze | E8: 22 oktober 2026
A9: K04 | B9: Zoekgebied | C9: Getekende ligging volgens EPSG 31984; buitenste draaikom E297534,598 / N7649611,919 | D9: Geometrie gemeten | E9: Ondergrondbestand ontbreekt voor nauwkeurige liggingstoets.
A10: K05 | B10: Toegelaten vloot | C10: Regulier T14,5m en L334m; geen 400m-schepen | D10: Overgenomen | E10: [2] T15m alleen na aparte dieptetoets
A11: K06 | B11: LNG-vloot | C11: GASLOG GREECE regulier, MOZAH alleen grensscenario | D11: Ontwerpvoorstel | E11: [2] Grotere LNG-vloot vraagt nieuwe breedtetoets
A12: K07 | B12: Verkeer | C12: Eenrichtingsgeul met VTS en loodsen | D12: Ontwerpvoorstel | E12: [3] Geen passeren in de hoofdgeul
A13: K08 | B13: Breedte | C13: Rechte geul 220 m, bocht circa 260 m bij R3400 m | D13: Gemeten + toets | E13: Nautiek; bocht en operationele omstandigheden nog onderbouwen.
A14: K09 | B14: Containerkranen | C14: 3/4/5 gelijktijdige kranen per schip, netto30 box/h | D14: Rekenaanname | E14: Productiviteit en bezetting in Containers
A15: K10 | B15: Terrein | C15: Containerterreinen 72,00 / 108,00 / 144,00 ha; graan 30,42 ha; RoRo 30,21 ha | D15: Gemeten DWG | E15: Gemeten contouren, geen afleiding uit referentiebeeld.
A16: K11 | B16: LNG-opslag | C16: ="Actief "&'Invoer'!$D$3&" tanks van 180000 m3; 4 basiscirkels en 3 uitgewerkte details" | D16: Voorlopige keuze | E16: D3 in Invoer is de enige actieve tankkeuze. Alle fasen dezelfde opstelling als rekenaanname.
A17: K12 | B17: Centrale | C17: Eindcapaciteit vanaf fase1; vermogensverdeling nog te kiezen | D17: Opdracht + rekenvoorbeeld | E17: 50% LNG naar centrale is illustratief
A18: K13 | B18: Baggergrond | C18: Niet voor reclamatie hergebruiken | D18: Opdrachtgegeven | E18: [4] Gemengd materiaal
A19: K14 | B19: Golfbrekers | C19: Voorhaven beschermen; type en kruin pas na golfontwerp | D19: Ontwerpvoorstel | E19: Geen ongefundeerde steen- of hoogteberekening
A20: K15 | B20: Voorkeurstoets | C20: Vier groepsschetsen beoordelen met dezelfde gegevens | D20: Nog af te ronden | E20: Afweging; geen fictieve scores
A21: K16 | B21: Definitieve toets | C21: DWG gemeten; opslagverdeling, ondergrond, plots en definitieve baggercontouren nog uitwerken | D21: Deels gecontroleerd | E21: Controle_Haven_DO.pdf van 23 oktober 2026; geen goedkeuring van ontbrekende gegevens.
A24: Wijzigingen voor de actuele rekenversie
A25: V3 | B25: Tekening | C25: Haven_DO.dwg van 23 oktober 2026 | D25: Verwerkt | E25: Kades, terreinen, route, diepten en terminaldetails gekoppeld.
A26: V3 | B26: Opslag | C26: Bruikbare slots en loodsgegevens blijven invulvelden | D26: Invoer nodig | E26: Geen fictieve slotcapaciteit uit de getekende oppervlakte afgeleid.
A27: V3 | B27: Nautiek | C27: Binnenste zwaaiplaats 670 m apart getoetst | D27: Onderbouwing nodig | E27: Buitenste 720 m blijft aanwezig; vergelijk met eerder criterium 701,4 m.
A28: V3 | B28: Grondwerk | C28: Nieuwe diepten en unieke deelvlakken | D28: Onvolledig | E28: Geen baggervolume zonder bestaande bodem en sluitende rekenvlakken.
A29: V3 | B29: Hoofdrapport | C29: Hoofdrapport en tekenbrief van 22 oktober | D29: Nog oude versie | E29: Het controleverslag beschrijft de verschillen; Excel is nu bijgewerkt.
