Workbook

Sheet Resultaten
A2: Havenontwerp Groep 1
A5: Ref | B5: Ontwerpresultaat | C5: Eenheid | D5: 2025 | E5: 2035 | F5: 2045 | G5: Betekenis
A6: R01 | B6: Containerligplaatsen vereist | C6: aantal | D6: ='Containers'!D15 | E6: ='Containers'!E15 | F6: ='Containers'!F15
A7: R02 | B7: Containerligplaatsen gepland | C7: aantal | D7: ='Containers'!D16 | E7: ='Containers'!E16 | F7: ='Containers'!F16
A8: R03 | B8: Bezetting containerkade | C8: deel | D8: ='Containers'!D17 | E8: ='Containers'!E17 | F8: ='Containers'!F17
A9: R04 | B9: Containerkade gepland | C9: m | D9: ='Containers'!D18 | E9: ='Containers'!E18 | F9: ='Containers'!F18
A10: R05 | B10: STS-kranen gelijktijdig | C10: aantal | D10: ='Containers'!D19 | E10: ='Containers'!E19 | F10: ='Containers'!F19
A11: R06 | B11: Containerterrein nodig | C11: ha | D11: ='Containers'!D27 | E11: ='Containers'!E27 | F11: ='Containers'!F27
A12: R07 | B12: Containerterrein reservering | C12: ha | D12: ='Containers'!D28 | E12: ='Containers'!E28 | F12: ='Containers'!F28
A13: R08 | B13: Graanopslag nodig | C13: ha | D13: ='Overige terminals'!D10 | E13: ='Overige terminals'!E10 | F13: ='Overige terminals'!F10
A14: R09 | B14: RoRo terrein nodig | C14: ha | D14: ='Overige terminals'!D16 | E14: ='Overige terminals'!E16 | F14: ='Overige terminals'!F16
A15: R10 | B15: LNG-calls afgerond | C15: calls/jaar | D15: ='Overige terminals'!D19 | E15: ='Overige terminals'!E19 | F15: ='Overige terminals'!F19
A16: R11 | B16: LNG opslagmarge | C16: m3 | D16: ='Overige terminals'!D25 | E16: ='Overige terminals'!E25 | F16: ='Overige terminals'!F25
A17: R12 | B17: LNG opslagmarge bij tank uit | C17: m3 | D17: ='Overige terminals'!D27 | E17: ='Overige terminals'!E27 | F17: ='Overige terminals'!F27
A18: R13 | B18: Centrale vermogen voorbeeld | C18: MW | D18: ='Overige terminals'!D30 | E18: ='Overige terminals'!E30 | F18: ='Overige terminals'!F30
A21: Nautische ruimtereservering voor je eigen tekening
B23: Rechte geulbreedte | C23: m | D23: =Nautiek!D20
B24: Bodemdiepte positief | C24: m MLWS | D24: =Nautiek!D25
B25: Draaicirkel diameter | C25: m | D25: =Nautiek!D28
B26: Havenmond | C26: m | D26: =Nautiek!D29
B29: Bagger- en reclamatievolume | D29: =IF(COUNT(Grondwerk!F10,Grondwerk!D25)=2,"SCHATTING BESCHIKBAAR","NOG NIET BEPAALD")
B31: Gebruik | D31: Gele invoercellen wijzigen; formules rekenen door.

Sheet Invoer
A2: Invoer
A5: Ref | B5: Parameter | C5: Eenheid | D5: 2025 | E5: 2035 | F5: 2045 | G5: Status | H5: Bron of motivering
A6: ct | B6: Containeroverslag | C6: TEU/jaar | D6: 1200000 | E6: 2000000 | F6: 4000000 | G6: Case | H6: [1] PPD-A p. 2
A7: bulk | B7: Graanoverslag | C7: ton/jaar | D7: 500000 | E7: 1000000 | F7: 1500000 | G7: Case | H7: [1] PPD-A p. 2
A8: roro | B8: Voertuigen | C8: auto/jaar | D8: 45000 | E8: 130000 | F8: 210000 | G8: Case | H8: [1] PPD-A p. 2
A9: lng | B9: LNG-overslag | C9: m3 LNG/jaar | D9: 4000000 | E9: 6000000 | F9: 8000000 | G9: Case | H9: [1] PPD-A p. 2
A10: days | B10: Kalenderdagen | C10: dagen/jaar | D10: 365 | E10: =$D10 | F10: =$D10 | G10: Definitie | H10: Geen schrikkeljaarcorrectie op conceptniveau
A11: avail | B11: Beschikbare ligplaatstijd | C11: deel | D11: 0.95 | E11: =$D11 | F11: =$D11 | G11: Rekenaanname | H11: 5% uitval door weer en onderhoud; gevoeligheid toetsen
A12: target | B12: Doelbezetting containerkade | C12: deel | D12: 0.65 | E12: =$D12 | F12: =$D12 | G12: Projectcriterium | H12: Planningsgrens; wachttijdmodel nog nodig
A13: ratio | B13: Aantal 20ft / aantal 40ft | C13: - | D13: 1.2 | E13: =$D13 | F13: =$D13 | G13: Case | H13: [1] Verhouding aantallen, niet verhouding TEU
A14: callC | B14: Overslag per containercall | C14: TEU/call | D14: 4500 | E14: =$D14 | F14: =$D14 | G14: Rekenaanname | H14: Zelfde callgrootte alle fasen; geen groei in scheepsafmetingen
A15: cranes | B15: Gelijktijdige STS-kranen per schip | C15: aantal | D15: 3 | E15: 4 | F15: 5 | G15: Ontwerpvoorstel | H15: Productiviteit is netto, incl. kleine stops
A16: qcrane | B16: Netto STS-productiviteit | C16: box/uur/kraan | D16: 30 | E16: =$D16 | F16: =$D16 | G16: Rekenaanname | H16: Te toetsen met operator; 20 geeft meer benodigde ligplaatsen
A17: moorC | B17: Tijd buiten containeroverslag | C17: uur/call | D17: 3 | E17: =$D17 | F17: =$D17 | G17: Rekenaanname | H17: Aan- en afmeren, checks en wisselen samen
A18: berths | B18: Geplande containerligplaatsen | C18: aantal | D18: 2 | E18: 3 | F18: 4 | G18: Ontwerpvoorstel | H18: Afhankelijk van afhandeling en wachttijdtoets
A19: module | B19: Containerkade per ligplaats | C19: m | D19: 400 | E19: =$D19 | F19: =$D19 | G19: Ontwerpvoorstel | H19: 334 m LOA + 2 x 30 m eindmarge = 394 m
A20: yard | B20: Te reserveren containerterrein | C20: ha | D20: 72 | E20: 108 | F20: 144 | G20: Ontwerpvoorstel | H20: DO-tekening: 72,0 / 108,0 / 144,0 ha gesloten polygonen (Maatstaat); gelijk aan reservering
A21: imp | B21: Aandeel import | C21: deel | D21: 0.5 | E21: =$D21 | F21: =$D21 | G21: Case | H21: [1] PPD-A p. 2
A22: exp | B22: Aandeel volle export | C22: deel | D22: 0.3 | E22: =$D22 | F22: =$D22 | G22: Case | H22: [1] PPD-A p. 2
A23: empty | B23: Aandeel lege export | C23: deel | D23: 0.2 | E23: =$D23 | F23: =$D23 | G23: Case | H23: [1] PPD-A p. 2
A24: dImp | B24: Verblijftijd import | C24: dagen | D24: 6 | E24: =$D24 | F24: =$D24 | G24: Case | H24: [1] PPD-A p. 2
A25: dExp | B25: Verblijftijd export | C25: dagen | D25: 4 | E25: =$D25 | F25: =$D25 | G25: Case | H25: [1] PPD-A p. 2
A26: dEmpty | B26: Verblijftijd leeg | C26: dagen | D26: 10 | E26: =$D26 | F26: =$D26 | G26: Case | H26: [1] PPD-A p. 2
A27: peak | B27: Piekfactor voorraad | C27: - | D27: 1.25 | E27: =$D27 | F27: =$D27 | G27: Rekenaanname | H27: Voor seizoens- en aankomstvariatie
A28: stack | B28: Effectieve gemiddelde stapeling | C28: TEU/slot | D28: 3 | E28: =$D28 | F28: =$D28 | G28: Rekenaanname | H28: Inclusief lagere stapeling voor bereikbaarheid
A29: util | B29: Benutting grondslots | C29: deel | D29: 0.7 | E29: =$D29 | F29: =$D29 | G29: Rekenaanname | H29: Operationele reserve
A30: slot | B30: Netto oppervlakte per TEU-slot | C30: m2 | D30: 28 | E30: =$D30 | F30: =$D30 | G30: Rekenaanname | H30: TEU-equivalent grondslot; niet box-slot
A31: support | B31: Terreinfactor containers / RoRo | C31: - | D31: 1.2 | E31: =$D31 | F31: =$D31 | G31: Rekenaanname | H31: Aanvulling voor apron, wegen en gebouwen
A32: callB | B32: Graan per scheepscall | C32: ton/call | D32: 65000 | E32: =$D32 | F32: =$D32 | G32: Rekenaanname | H32: Binnen 81.290 DWT; DWT is niet volledig laadvermogen
... A74: vesselSpeed | B74: Concept vaarsnelheid | C74: knopen | D74: 6 | E74: =$D74 | F74: =$D74 | G74: Rekenaanname | H74: PIANC slow: 5 tot 8 knopen
A78: Bronnenregister - invoerstatus is bepalend, getallen zonder bron zijn projectaannamen
A79: Ref | B79: Titel | C79: Auteur | H79: Bestand of link
A80: [1] | B80: PPD-A Case Study | C80: NHL Stenden | H80: Cursusbestand, p.1-4; onderwijsvolumes en randvoorwaarden
A81: [2] | B81: Rapport_groep1_26-27 en scheepsonderzoek ontwerpgrenzen | C81: Projectgroep 1 | H81: Huidige documenten, gelezen 22-10-2026; brongegevens schepen als invoer
A82: [3] | B82: Harbour Approach Channels Design Guidelines WG121 | C82: PIANC 2014 | H82: Aangeleverd cursus-PDF; par.3.1.5, tab.3.4-3.6, p.86-89
A83: [4] | B83: Porto Central soil information | C83: NHL Stenden | H83: Cursusbestand, bodemverdeling en verbod hergebruik
A84: [5] | B84: Terminal Visit 16/09/22 | C84: Gate terminal 2022 | H84: Aangeleverd cursusbestand, slides6-8: 600,7MWh/m3,3tanks totaal540000m3
A85: [6] | B85: O Caso Porto Central | C85: Porto Central / José Ferro da Cunha Lima 2016 | H85: https://portal.antt.gov.br/documents/20122/358563/jose_ferro_lima__porto_central.pdf/2f561adb-51c5-7d3b-f7e6-f9c4d289e328?download=true&t=1591713905387&version=1.0
A86: [7] | B86: About Porto Central / Layout | C86: Porto Central | H86: https://www.portocentral.com.br/en/o-porto/
A87: [8] | B87: Phase1 construction update | C87: Porto Central 16-09-2026 | H87: https://www.portocentral.com.br/en/blog/porto-central-avanca-nas-obras-da-fase-1-e-prepara-inicio-da-infraestrutura-maritima/

Sheet Nautiek
A2: Nautiek
A5: Ref | B5: Breedtecomponent | C5: Factor B | D5: Meter | E5: Status | F5: Bron | H5: Voorwaarde
A6: N01 | B6: Basismanoeuvreerbaan | C6: 1.5 | D6: =C6*Invoer!D62 | F6: PIANC tab.3.4 | H6: Containerschip matig manoeuvreerbaar
A7: N02 | B7: Vaarsnelheid | C7: 0 | D7: =C7*Invoer!D62 | F7: PIANC tab.3.5(a) | H7: 6kn, slow: geen aparte snelheidsbreedte
A8: N03 | B8: Dwarswind | C8: 0.6 | D8: =C8*Invoer!D62 | F8: PIANC tab.3.5(b) | H8: Moderate15-33kn; operationele grens nog toetsen
A9: N04 | B9: Dwarsstroom | C9: 1 | D9: =C9*Invoer!D62 | F9: PIANC tab.3.5(c) | H9: Moderate0,5-1,5kn; conservatieve onbevestigde klasse
A10: N05 | B10: Langsstroom | C10: 0 | D10: =C10*Invoer!D62 | F10: PIANC tab.3.5(d) | H10: Laag <1,5kn aangenomen
A11: N06 | B11: Golven dwars / schuin achter | C11: 0.5 | D11: =C11*Invoer!D62 | F11: PIANC tab.3.5(e) | H11: Hs1-3m, richting nog vast te leggen
A12: N07 | B12: Navigatiehulpmiddelen | C12: 0 | D12: =C12*Invoer!D62 | F12: PIANC tab.3.5(f) | H12: Goede betonning, loodsen en DGPS voorzien
A13: N08 | B13: Bodemoppervlak | C13: =IF(D25/Invoer!D63>=1.5,0,0.2) | D13: =C13*Invoer!D62 | F13: PIANC tab.3.5(g) | H13: Conservatief hard/ruw; h<1,5T
A14: N09 | B14: Relatieve waterdiepte | C14: =IF(D25/Invoer!D63>=1.5,0,IF(D25/Invoer!D63>=1.25,0.1,0.2)) | D14: =C14*Invoer!D62 | F14: PIANC tab.3.5(h) | H14: 1,25 <= h/T <1,5 voor buitengeul
A15: N10 | B15: Oevermarge links | C15: 0.3 | D15: =C15*Invoer!D62 | F15: PIANC tab.3.6 | H15: Talud/ondiepte, slow; geen harde verticale oever
A16: N11 | B16: Oevermarge rechts | C16: 0.3 | D16: =C16*Invoer!D62 | F16: PIANC tab.3.6 | H16: Talud/ondiepte, slow; geen harde verticale oever
B18: Som breedtefactoren | C18: =SUM(C6:C16)
B19: Benodigde rechte buitengeul | C19: m | D19: =C18*Invoer!D62
B20: Voorgestelde geulbreedte | C20: m | D20: =ROUNDUP(D19/10,0)*10
A22: Verticale maatvoering en manoeuvreren
A24: N12 | B24: Som benodigde diepte | C24: m | D24: =SUM(Invoer!D63,Invoer!D64,Invoer!D65,Invoer!D66,Invoer!D67,Invoer!D68,Invoer!D69) | H24: Alle componenten als invoer zichtbaar
A25: N13 | B25: Ontwerpdiepte incl. reserve | C25: m MLWS | D25: =D24+Invoer!D70 | H25: Positieve diepte; CAD-bodemhoogte = -waarde
A26: N14 | B26: Verhouding h/T | C26: - | D26: =D25/Invoer!D63 | H26: Controle op gekozen dieptefactor
A27: N15 | B27: Vereiste draaicirkel | C27: m | D27: =Invoer!D71*Invoer!D61 | H27: Projectcriterium, geen universele richtlijn
A28: N16 | B28: Gereserveerde draaicirkel | C28: m | D28: =Invoer!D72 | H28: Eigen plattegrond moet vrij vlak aantonen
A29: N17 | B29: Havenmond | C29: m | D29: =Invoer!D73 | H29: Tussen obstakels op bodemniveau toetsen
A30: N18 | B30: Marge kanaalbreedte | C30: m | D30: =D20-D19 | H30: Geen extra veiligheidsklasse
A31: N19 | B31: Kanaallengte | C31: m | D31: 19720 | G31: VOORLOPIG | H31: DO-tekening: 18.000 m buiten de mond (eindpunt A5 nog op -18,2 m MLWS-lijn leggen) + 1.720 m mond-draaikom
A32: N20 | B32: Indicatieve vaartijd enkele reis | C32: uur | D32: =IF(COUNT(D31)=1,D31/(Invoer!D74*1852),"") | H32: Vaartijd exclusief scheiding, sleepboten en wachten
A35: Gevoeligheid bij dezelfde omstandigheden
A36: Ref | B36: Schipscenario | C36: Breedte m | D36: Basisfactor | E36: Extra factor | F36: Benodigde m | G36: Status
A37: S1 | B37: Reguliere container | C37: 48.2 | D37: 1.5 | E37: 0 | F37: =C37*($C$18-$C$6+D37+E37) | G37: =IF(F37<=$D$20,"BINNEN BREEDTE","EXTRA BREEDTE")
A38: S2 | B38: GASLOG GREECE | C38: 45.8 | D38: 1.5 | E38: 0 | F38: =C38*($C$18-$C$6+D38+E38) | G38: =IF(F38<=$D$20,"BINNEN BREEDTE","EXTRA BREEDTE")
A39: S3 | B39: KIRA OLDENDORFF | C39: 32.26 | D39: 1.8 | E39: 0 | F39: =C39*($C$18-$C$6+D39+E39) | G39: =IF(F39<=$D$20,"BINNEN BREEDTE","EXTRA BREEDTE")
A40: S4 | B40: BYD SHENZHEN | C40: 37.7 | D40: 1.5 | E40: 0.2 | F40: =C40*($C$18-$C$6+D40+E40) | G40: =IF(F40<=$D$20,"BINNEN BREEDTE","EXTRA BREEDTE")
A41: S5 | B41: MOZAH grensscenario | C41: 53.8 | D41: 1.5 | E41: 0 | F41: =C41*($C$18-$C$6+D41+E41) | G41: =IF(F41<=$D$20,"BINNEN BREEDTE","EXTRA BREEDTE")

Sheet Containers
A2: Containers
A5: Ref | B5: Berekening | C5: Eenheid | D5: 2025 | E5: 2035 | F5: 2045 | G5: Status | H5: Toelichting
A6: C01 | B6: TEU per fysieke container | C6: TEU/box | D6: =(Invoer!D13+2)/(Invoer!D13+1) | E6: =(Invoer!E13+2)/(Invoer!E13+1) | F6: =(Invoer!F13+2)/(Invoer!F13+1) | H6: N20 = 1,2 N40; box is één fysieke container
A7: C02 | B7: Jaarlijkse kraanbewegingen | C7: box/jaar | D7: =Invoer!D6/D6 | E7: =Invoer!E6/E6 | F7: =Invoer!F6/F6 | H7: Eén kadetransfer per box; rehandles apart
A8: C03 | B8: Gemiddelde containercalls | C8: calls/jaar | D8: =Invoer!D6/Invoer!D14 | E8: =Invoer!E6/Invoer!E14 | F8: =Invoer!F6/Invoer!F14 | H8: Gemiddeld; afgeronde planning staat eronder
A9: C04 | B9: Calls afgerond naar boven | C9: calls/jaar | D9: =ROUNDUP(D8,0) | E9: =ROUNDUP(E8,0) | F9: =ROUNDUP(F8,0) | H9: Voor planning en verkeersbelasting
A10: C05 | B10: Kraanbewegingen per call | C10: box/call | D10: =Invoer!D14/D6 | E10: =Invoer!E14/E6 | F10: =Invoer!F14/F6 | H10: Parcel is kadedoorzet; geen gehele scheepscapaciteit
A11: C06 | B11: Effectieve scheepsproductiviteit | C11: box/uur | D11: =Invoer!D15*Invoer!D16 | E11: =Invoer!E15*Invoer!E16 | F11: =Invoer!F15*Invoer!F16 | H11: Netto productiviteit per kraan x gelijktijdige kranen
A12: C07 | B12: Overslag plus overige tijd | C12: uur/call | D12: =D10/D11+Invoer!D17 | E12: =E10/E11+Invoer!E17 | F12: =F10/F11+Invoer!F17 | H12: Vervangt de oude vaste aanname van 28 uur
A13: C08 | B13: Ligplaatsuren totaal | C13: uur/jaar | D13: =D9*D12 | E13: =E9*E12 | F13: =F9*F12 | H13: Afgeronde calls voor conservatieve bezetting
A14: C09 | B14: Beschikbare uren per berth | C14: uur/jaar | D14: =Invoer!D10*24*Invoer!D11 | E14: =Invoer!E10*24*Invoer!E11 | F14: =Invoer!F10*24*Invoer!F11 | H14: 5% totale berthuitval als ontwerphypothese
A15: C10 | B15: Benodigde containerligplaatsen | C15: aantal | D15: =ROUNDUP(D13/(D14*Invoer!D12),0) | E15: =ROUNDUP(E13/(E14*Invoer!E12),0) | F15: =ROUNDUP(F13/(F14*Invoer!F12),0) | H15: Toets is capaciteitsberekening, geen wachtrijbewijs
A16: C11 | B16: Geplande containerligplaatsen | C16: aantal | D16: =Invoer!D18 | E16: =Invoer!E18 | F16: =Invoer!F18 | H16: Intekenen na keuze
A17: C12 | B17: Bezetting geplande kades | C17: deel | D17: =D13/(D14*D16) | E17: =E13/(E14*E16) | F17: =F13/(F14*F16) | H17: Vergeleken met projectcriterium 65%
A18: C13 | B18: Geplande containerkade | C18: m | D18: =D16*Invoer!D19 | E18: =E16*Invoer!E19 | F18: =F16*Invoer!F19 | H18: 400 m per berth als module
A19: C14 | B19: STS-kranen in operatie | C19: aantal | D19: =D16*Invoer!D15 | E19: =E16*Invoer!E15 | F19: =F16*Invoer!F15 | H19: Gelijktijdig bij volledige bezetting; geen onderhoudsreserve
A20: C15 | B20: Gewogen verblijftijd | C20: dagen | D20: =Invoer!D21*Invoer!D24+Invoer!D22*Invoer!D25+Invoer!D23*Invoer!D26 | E20: =Invoer!E21*Invoer!E24+Invoer!E22*Invoer!E25+Invoer!E23*Invoer!E26 | F20: =Invoer!F21*Invoer!F24+Invoer!F22*Invoer!F25+Invoer!F23*Invoer!F26 | H20: 6,2 dagen volgens case
A21: C16 | B21: Piekvoorraad import | C21: TEU | D21: =Invoer!D6*Invoer!D21*Invoer!D24/Invoer!D10*Invoer!D27 | E21: =Invoer!E6*Invoer!E21*Invoer!E24/Invoer!E10*Invoer!E27 | F21: =Invoer!F6*Invoer!F21*Invoer!F24/Invoer!F10*Invoer!F27 | H21: TEU-dagen; geen extra conversie naar box
A22: C17 | B22: Piekvoorraad volle export | C22: TEU | D22: =Invoer!D6*Invoer!D22*Invoer!D25/Invoer!D10*Invoer!D27 | E22: =Invoer!E6*Invoer!E22*Invoer!E25/Invoer!E10*Invoer!E27 | F22: =Invoer!F6*Invoer!F22*Invoer!F25/Invoer!F10*Invoer!F27
A23: C18 | B23: Piekvoorraad lege export | C23: TEU | D23: =Invoer!D6*Invoer!D23*Invoer!D26/Invoer!D10*Invoer!D27 | E23: =Invoer!E6*Invoer!E23*Invoer!E26/Invoer!E10*Invoer!E27 | F23: =Invoer!F6*Invoer!F23*Invoer!F26/Invoer!F10*Invoer!F27
A24: C19 | B24: Piekvoorraad totaal | C24: TEU | D24: =SUM(D21:D23) | E24: =SUM(E21:E23) | F24: =SUM(F21:F23) | H24: Som van drie stromen
A25: C20 | B25: Benodigde TEU-grondslots | C25: slots | D25: =D24/(Invoer!D28*Invoer!D29) | E25: =E24/(Invoer!E28*Invoer!E29) | F25: =F24/(Invoer!F28*Invoer!F29) | H25: 3 hoog bij 70% slotbenutting
A26: C21 | B26: Netto opslagoppervlakte | C26: ha | D26: =D25*Invoer!D30/10000 | E26: =E25*Invoer!E30/10000 | F26: =F25*Invoer!F30/10000 | H26: 28 m2 per TEU-grondslot
A27: C22 | B27: Containerterminal totaal | C27: ha | D27: =D26*Invoer!D31 | E27: =E26*Invoer!E31 | F27: =F26*Invoer!F31 | H27: Netto opslag x 1,2; equipmentindeling toetsen
A28: C23 | B28: Reservering containerterrein | C28: ha | D28: =Invoer!D20 | E28: =Invoer!E20 | F28: =Invoer!F20 | H28: Doelwaarde voor eigen tekening
A29: C24 | B29: Marge terrein | C29: ha | D29: =D28-D27 | E29: =E28-E27 | F29: =F28-F27 | H29: Positief = reservering groter dan berekend
A30: C25 | B30: Capaciteitstoets kades | C30: - | D30: =IF(D15<=D16,"VOLDOET REKENKUNDIG","MEER CAPACITEIT NODIG") | E30: =IF(E15<=E16,"VOLDOET REKENKUNDIG","MEER CAPACITEIT NODIG") | F30: =IF(F15<=F16,"VOLDOET REKENKUNDIG","MEER CAPACITEIT NODIG") | H30: Geen garantie voor korte wachttijden

Sheet Overige terminals
A2: Overige terminals
A5: Ref | B5: Berekening | C5: Eenheid | D5: 2025 | E5: 2035 | F5: 2045 | G5: Status | H5: Toelichting
A6: T01 | B6: Graancalls afgerond | C6: calls/jaar | D6: =ROUNDUP(Invoer!D7/Invoer!D32,0) | E6: =ROUNDUP(Invoer!E7/Invoer!E32,0) | F6: =ROUNDUP(Invoer!F7/Invoer!F32,0) | H6: 65000 ton per call als conceptparcel
A7: T02 | B7: Graan ligplaatstijd | C7: uur/call | D7: =Invoer!D32/Invoer!D33+Invoer!D34 | E7: =Invoer!E32/Invoer!E33+Invoer!E34 | F7: =Invoer!F32/Invoer!F33+Invoer!F34 | H7: Bij constante netto beladerproductiviteit
A8: T03 | B8: Bezetting één graanligplaats | C8: deel | D8: =D6*D7/(Invoer!D10*24*Invoer!D11) | E8: =E6*E7/(Invoer!E10*24*Invoer!E11) | F8: =F6*F7/(Invoer!F10*24*Invoer!F11) | H8: Piekcampagnes apart toetsen
A9: T04 | B9: Graan piekvoorraad | C9: ton | D9: =Invoer!D7*Invoer!D35/Invoer!D10*Invoer!D27 | E9: =Invoer!E7*Invoer!E35/Invoer!E10*Invoer!E27 | F9: =Invoer!F7*Invoer!F35/Invoer!F10*Invoer!F27 | H9: 30 dagen met piekfactor 1,25
A10: T05 | B10: Graan opslagruimte | C10: ha | D10: =D9/Invoer!D36/Invoer!D37*Invoer!D38/10000 | E10: =E9/Invoer!E36/Invoer!E37*Invoer!E38/10000 | F10: =F9/Invoer!F36/Invoer!F37*Invoer!F38/10000 | H10: Effectieve hoogte en dichtheid zijn aannamen
A11: T06 | B11: Graanterrein reservering | C11: ha | D11: =Invoer!D39 | E11: =Invoer!E39 | F11: =Invoer!F39 | H11: Inclusief groei en logistieke functies
A12: T07 | B12: RoRo calls afgerond | C12: calls/jaar | D12: =ROUNDUP(Invoer!D8/Invoer!D40,0) | E12: =ROUNDUP(Invoer!E8/Invoer!E40,0) | F12: =ROUNDUP(Invoer!F8/Invoer!F40,0) | H12: 6500 auto/call; lagere parcel geeft meer calls
A13: T08 | B13: RoRo ligplaatstijd | C13: uur/call | D13: =Invoer!D40/Invoer!D41+Invoer!D42 | E13: =Invoer!E40/Invoer!E41+Invoer!E42 | F13: =Invoer!F40/Invoer!F41+Invoer!F42 | H13: Netto150 auto/uur als hypothese
A14: T09 | B14: Bezetting één RoRo-ligplaats | C14: deel | D14: =D12*D13/(Invoer!D10*24*Invoer!D11) | E14: =E12*E13/(Invoer!E10*24*Invoer!E11) | F14: =F12*F13/(Invoer!F10*24*Invoer!F11) | H14: Rampconflicten nog toetsen
A15: T10 | B15: RoRo piekvoorraad | C15: auto | D15: =Invoer!D8*Invoer!D43/Invoer!D10*Invoer!D44 | E15: =Invoer!E8*Invoer!E43/Invoer!E10*Invoer!E44 | F15: =Invoer!F8*Invoer!F43/Invoer!F10*Invoer!F44
A16: T11 | B16: RoRo oppervlakte totaal | C16: ha | D16: =D15*Invoer!D45*Invoer!D31/10000 | E16: =E15*Invoer!E45*Invoer!E31/10000 | F16: =F15*Invoer!F45*Invoer!F31/10000 | H16: 30m2 inclusief rijruimte, 20% extra support
A17: T12 | B17: RoRo terrein reservering | C17: ha | D17: =Invoer!D46 | E17: =Invoer!E46 | F17: =Invoer!F46 | H17: Aanpassen als eigen tekening andere oppervlakte heeft
A18: T13 | B18: LNG effectieve scheepslading | C18: m3/call | D18: =Invoer!D47*Invoer!D48 | E18: =Invoer!E47*Invoer!E48 | F18: =Invoer!F47*Invoer!F48 | H18: Reguliere vloot; geen MOZAH
A19: T14 | B19: LNG calls afgerond | C19: calls/jaar | D19: =ROUNDUP(Invoer!D9/D18,0) | E19: =ROUNDUP(Invoer!E9/E18,0) | F19: =ROUNDUP(Invoer!F9/F18,0) | H19: Afgeronde calls voor berthbezetting
A20: T15 | B20: LNG ligplaatstijd | C20: uur/call | D20: =D18/Invoer!D49+Invoer!D50 | E20: =E18/Invoer!E49+Invoer!E50 | F20: =F18/Invoer!F49+Invoer!F50 | H20: 10000m3/uur + 8 uur overige tijd
A21: T16 | B21: Bezetting één LNG-steiger | C21: deel | D21: =D19*D20/(Invoer!D10*24*Invoer!D11) | E21: =E19*E20/(Invoer!E10*24*Invoer!E11) | F21: =F19*F20/(Invoer!F10*24*Invoer!F11) | H21: Geen LNG-operability of QRA-bewijs
A22: T17 | B22: Nominale LNG-opslag | C22: m3 | D22: =Invoer!D51*Invoer!D52 | E22: =Invoer!E51*Invoer!E52 | F22: =Invoer!F51*Invoer!F52 | H22: Alle drie tanks vanaf fase1 als voorstel
A23: T18 | B23: Operationele opslagband | C23: m3 | D23: =D22*(Invoer!D54-Invoer!D53) | E23: =E22*(Invoer!E54-Invoer!E53) | F23: =F22*(Invoer!F54-Invoer!F53) | H23: Tussen 10% en90% vulling, totaal80% nominaal
A24: T19 | B24: Buffer plus ontvangstruimte | C24: m3 | D24: =Invoer!D9/Invoer!D10*Invoer!D55+D18 | E24: =Invoer!E9/Invoer!E10*Invoer!E55+E18 | F24: =Invoer!F9/Invoer!F10*Invoer!F55+F18 | H24: 7 dagen gemiddelde vraag + volledige scheepsparcel
A25: T20 | B25: Opslagmarge | C25: m3 | D25: =D23-D24 | E25: =E23-E24 | F25: =F23-F24 | H25: Positief vereist onder gekozen voorraadbeleid
A26: T21 | B26: Opslagband bij één tank uit | C26: m3 | D26: =MAX(0,Invoer!D51-1)*Invoer!D52*(Invoer!D54-Invoer!D53) | E26: =MAX(0,Invoer!E51-1)*Invoer!E52*(Invoer!E54-Invoer!E53) | F26: =MAX(0,Invoer!F51-1)*Invoer!F52*(Invoer!F54-Invoer!F53) | H26: N-1 toets; operationele eis nog te kiezen
A27: T22 | B27: Marge bij één tank uit | C27: m3 | D27: =D26-D24 | E27: =E26-E24 | F27: =F26-F24 | H27: Negatief vraagt lager bufferbeleid of extra tank
A28: T23 | B28: Gas naar regionaal systeem | C28: Nm3/jaar | D28: =Invoer!D9*Invoer!D56 | E28: =Invoer!E9*Invoer!E56 | F28: =Invoer!F9*Invoer!F56 | H28: Inclusief gas richting centrale; geen extra gasproductie
A29: T24 | B29: Elektriciteitsproductie voorbeeld | C29: MWh/jaar | D29: =Invoer!D9*Invoer!D57*Invoer!D58*Invoer!D59 | E29: =Invoer!E9*Invoer!E57*Invoer!E58*Invoer!E59 | F29: =Invoer!F9*Invoer!F57*Invoer!F58*Invoer!F59 | H29: 50% LNG naar centrale, rendement60% als rekenvoorbeeld
A30: T25 | B30: Centrale eindcapaciteit voorbeeld | C30: MW | D30: =Invoer!F9*Invoer!F57*Invoer!F58*Invoer!F59/(Invoer!F10*24*Invoer!F60) | E30: =Invoer!F9*Invoer!F57*Invoer!F58*Invoer!F59/(Invoer!F10*24*Invoer!F60) | F30: =Invoer!F9*Invoer!F57*Invoer!F58*Invoer!F59/(Invoer!F10*24*Invoer!F60) | H30: Alle fasen: vermogen bij einddoorzet. Niet vastgesteld.
A33: Verkeer voor hoofdgeul en verkeersplanning
B35: Aanlopen alle ladingstromen | C35: calls/jaar | D35: =Containers!D9+D6+D12+D19 | E35: =Containers!E9+E6+E12+E19 | F35: =Containers!F9+F6+F12+F19
B36: Aankomst plus vertrek | C36: bewegingen/jaar | D36: =2*D35 | E36: =2*E35 | F36: =2*F35
B37: Gemiddelde geulbewegingen | C37: per dag | D37: =D36/Invoer!D10 | E37: =E36/Invoer!E10 | F37: =F36/Invoer!F10

Sheet Grondwerk
A2: Grondwerk
A5: Zone | B5: Baggervak | C5: Oppervlakte m2 | D5: Bestaande diepte m | E5: Ontwerpdiepte m | F5: Volume m3 | G5: Status | H5: Invoerbron
A6: 1 | B6: Havenbekken | C6: 2606110 | E6: =Nautiek!D25 | F6: =IF(COUNT(C6:E6)=3,C6*MAX(0,E6-D6),"") | G6: =IF(COUNT(C6:D6)<2,"INVOER ONTBREEKT","GEMIDDELDE-SCHATTING") | H6: DO: binnenbekken F1-F3 + voorhaven + LNG-insteek (gesloten vlakken, Maatstaat). Bestaande diepte nog invullen.
A7: 2 | B7: Geul tot DHN -15m | E7: =Nautiek!D25 | F7: =IF(COUNT(C7:E7)=3,C7*MAX(0,E7-D7),"") | G7: =IF(COUNT(C7:D7)<2,"INVOER ONTBREEKT","GEMIDDELDE-SCHATTING") | H7: DO: geul buiten de mond totaal 3.960.000 m2 (220 x 18.000 m); splitsen op DHN -15 m-contour.
A8: 3 | B8: Geul voorbij DHN -15m | E8: =Nautiek!D25 | F8: =IF(COUNT(C8:E8)=3,C8*MAX(0,E8-D8),"") | G8: =IF(COUNT(C8:D8)<2,"INVOER ONTBREEKT","GEMIDDELDE-SCHATTING") | H8: Zie H7; oppervlak pas invullen na splitsing op de dieptelijn.
B10: Totaal uit gemiddelde diepten | F10: =IF(COUNT(F6:F8)=3,SUM(F6:F8),"") | G10: =IF(COUNT(F6:F8)=3,"SCHATTING","NIET BEPAALD")
A12: Bodemverdeling volgens cursus - materiaal niet herbruikbaar voor reclamatie
A13: Zone | B13: Gebied | C13: Zand | D13: Zachte klei | E13: Stevige/harde klei | F13: Som | G13: Status
A14: 1 | B14: Havenbekken | C14: 0.2 | D14: 0.3 | E14: 0.5 | F14: =SUM(C14:E14) | G14: =IF(ABS(F14-1)<0.000001,"100%","CONTROLEER")
A15: 2 | B15: Geul tot DHN -15m | C15: 0.5 | D15: 0.15 | E15: 0.35 | F15: =SUM(C15:E15) | G15: =IF(ABS(F15-1)<0.000001,"100%","CONTROLEER")
A16: 3 | B16: Geul voorbij DHN -15m | C16: 0.5 | D16: 0.3 | E16: 0.2 | F16: =SUM(C16:E16) | G16: =IF(ABS(F16-1)<0.000001,"100%","CONTROLEER")
A19: Reclamatie met gemiddeld landniveau - extern geschikt materiaal nodig
A20: Ref | B20: Onderdeel | C20: Eenheid | D20: Waarde | E20: Status | F20: Toelichting
A21: G1 | B21: Te vullen oppervlakte | C21: m2 | D21: 3229941 | E21: Gemeten DO | F21: Terminals, LNG-zone, centrale en havendienst; exclusief reserveterreinen.
A22: G2 | B22: Bestaande gemiddelde hoogte | C22: m t.o.v. datum
A23: G3 | B23: Ontwerp bovenzijde | C23: m zelfde datum
A24: G4 | B24: Extra laag voor zetting | C24: m
B25: Vulvolume schatting | C25: m3 | D25: =IF(COUNT(D21:D24)=4,D21*MAX(0,D23-D22+D24),"") | E25: =IF(COUNT(D21:D24)=4,"SCHATTING","INVOER ONTBREEKT")
B28: Methode voor definitieve volumes | H28: TIN/cellen: som oppervlak x MAX(0, ontwerpdiepte - bestaande diepte).

Sheet Afweging
A2: Afweging
A5: Ref | B5: Criterium | C5: Gewicht | D5: A lineair | E5: B referentie | F5: C offshore | G5: D gescheiden | H5: Bewijs nodig
A6: M1 | B6: Bevaarbaarheid | C6: 0.3 | H6: Simulatie, toegangsroute en vrije draaicirkel
A7: M2 | B7: Baggeren en reclameren | C7: 0.25 | H7: Geometrie, bathymetrie, grondsoort en volume
A8: M3 | B8: Complexiteit aanleg | C8: 0.2 | H8: Dammen, funderingen, uitvoeringsvolgorde
A9: M4 | B9: Fasering en uitbreidbaarheid | C9: 0.15 | H9: Bouwen tijdens exploitatie en grondreserveringen
A10: M5 | B10: Milieu en LNG-scheiding | C10: 0.1 | H10: Ecologie, baggerstort, QRA en koelwater
B12: Som gewichten | C12: =SUM(C6:C10)
B14: Gewogen score 1 tot 5 | D14: =IF(AND(COUNT(D6:D10)=5,ABS($C$12-1)<0.000001),SUMPRODUCT($C$6:$C$10,D6:D10),"") | E14: =IF(AND(COUNT(E6:E10)=5,ABS($C$12-1)<0.000001),SUMPRODUCT($C$6:$C$10,E6:E10),"") | F14: =IF(AND(COUNT(F6:F10)=5,ABS($C$12-1)<0.000001),SUMPRODUCT($C$6:$C$10,F6:F10),"") | G14: =IF(AND(COUNT(G6:G10)=5,ABS($C$12-1)<0.000001),SUMPRODUCT($C$6:$C$10,G6:G10),"")
B16: Huidige voorkeursrichting | D16: Porto Central als vormreferentie
B18: Status vergelijking | D18: =IF(COUNT(D14:G14)=4,"VOLLEDIG INGEVOERD","GROEPSSCHETSEN EN SCORES NODIG")
H20: Vul alleen scores in met motivering. 1 ongunstig, 5 gunstig. De oude 4,35-score geldt niet voor dit ontwerp.

Sheet Keuzes
A2: Keuzes
A5: Ref | B5: Onderwerp | C5: Besluit of voorstel | D5: Status | E5: Onderbouwing
A6: K01 | B6: Groep 1 programma | C6: Containers, graan, voertuigen, LNG en centrale | D6: Opdracht | E6: [1]
A7: K02 | B7: Havenvorm | C7: Porto Central als referentie voor bekken, vingers en golfbrekers | D7: Gebruikerskeuze | E7: Beelden gebruiker + [6]
A8: K03 | B8: Tekenwerk | C8: Gebruiker maakt eigen tekeningen | D8: Gebruikerskeuze | E8: 22 oktober 2026
A9: K04 | B9: Zoekgebied | C9: Locatie B uit Deel 1; exacte inpassing open | D9: Overgenomen | E9: [2] Geen gelijkstelling aan werkelijke Porto Central
A10: K05 | B10: Toegelaten vloot | C10: Regulier T14,5m en L334m; geen 400m-schepen | D10: Overgenomen | E10: [2] T15m alleen na aparte dieptetoets
A11: K06 | B11: LNG-vloot | C11: GASLOG GREECE regulier, MOZAH alleen grensscenario | D11: Ontwerpvoorstel | E11: [2] Grotere LNG-vloot vraagt nieuwe breedtetoets
A12: K07 | B12: Verkeer | C12: Eenrichtingsgeul met VTS en loodsen | D12: Ontwerpvoorstel | E12: [3] Geen passeren in de hoofdgeul
A13: K08 | B13: Breedte | C13: PIANC conceptmethode met matige dwarsstroom | D13: Rekenaanname | E13: Nautiek!D20 is leidend; oude 200m vervalt als basis
A14: K09 | B14: Containerkranen | C14: 3/4/5 gelijktijdige kranen per schip, netto30 box/h | D14: Rekenaanname | E14: Productiviteit en bezetting in Containers
A15: K10 | B15: Terrein | C15: 72/108/144ha containers,30ha graan en30ha RoRo | D15: Ontwerpvoorstel | E15: Nog te tekenen; niet uit referentiebeeld gemeten
A16: K11 | B16: LNG-opslag | C16: 3x180000m3; N-1 in eindfase onder gekozen buffer ontoereikend | D16: Ontwerpvoorstel | E16: Overige terminals r22-27
... A34: K29 | B34: Variantafweging | C34: Niet door de tekenaar ingevuld: de groep scoort de eigen schetsen met motivering. | D34: Open | E34: Besluitenlijst B13; vervolg: Tabblad Afweging invullen per groepslid-schets.

Sheet Tekening_DO
A1: Maatstaat uit Haven_DO (gemeten in de tekening) - zie ook Maatstaat_en_coordinaten.xlsx
A2: Onderdeel | B2: Eenheid | C2: Gemeten DO | D2: Rekenboek/eis | E2: Cel / bron | F2: Status
A3: Hoofdgeul bodembreedte | B3: m | C3: 220 | D3: 220 | E3: Nautiek D20 | F3: rekenuitkomst
A4: Bodemhoogte geul en bekkens | B4: m MLWS | C4: -18.2 | D4: -18.2 | E4: Nautiek D25 | F4: voorlopig
A5: Geullengte buiten havenmond | B5: m | C5: 18000 | E5: Nautiek D31 | F5: VOORLOPIG
A6: Vaarafstand geuleinde - draaikom | B6: m | C6: 19720 | E6: Nautiek D31 | F6: VOORLOPIG
A7: Vrije draaikom diameter | B7: m | C7: 720 | D7: 720 | E7: Nautiek D28 | F7: vrij getoetst
A8: Draaikom tot afgemeerde schepen | B8: m | C8: 170 | D8: >0 | F8: voldoet
A9: Draaikom tot kades/dammen | B9: m | C9: 220 | D9: >0 | F9: voldoet
A10: Havenmond vrij tussen footprints | B10: m | C10: 350 | D10: 350 | E10: Nautiek D29 | F10: voldoet
A11: Stopweg havenmond - draaikom | B11: m | C11: 1720 | D11: 1670 | E11: 5 x LOA | F11: voldoet
A12: Sleepbootkoppelpunt buiten mond | B12: m | C12: 1500 | E12: rapport 5.1 | F12: ingetekend
A13: Containerkade fase 1 | B13: m | C13: 802.19218 | D13: 800 | E13: Containers D18 | F13: gelijk
A14: Containerkade fase 2 | B14: m | C14: 1203.2883 | D14: 1200 | E14: Containers E18 | F14: gelijk
A15: Containerkade fase 3 | B15: m | C15: 1604.3844 | D15: 1600 | E15: Containers F18 | F15: gelijk
A16: Containerterrein fase 1 | B16: ha | C16: 72 | D16: 72 | E16: Invoer D20 (vraag 40,8) | F16: gelijk
A17: Containerterrein fase 2 | B17: ha | C17: 108 | D17: 108 | E17: Invoer E20 (vraag 67,9) | F17: gelijk
A18: Containerterrein fase 3 | B18: ha | C18: 144 | D18: 144 | E18: Invoer F20 (vraag 135,9) | F18: gelijk
A19: Graankade | B19: m | C19: 300 | D19: 300 | E19: rapport 8.1 | F19: gelijk
A20: Graanterrein | B20: ha | C20: 30.4 | D20: 30 | E20: Invoer D39 (vraag 5,1) | F20: gelijk
A21: RoRo-kade | B21: m | C21: 300 | D21: 300 | E21: rapport 8.2 | F21: gelijk
A22: RoRo-terrein | B22: ha | C22: 30.2 | D22: 30 | E22: Invoer D46 (vraag 26,9) | F22: gelijk
A23: Draaikom binnenhaven (graan/RoRo) | B23: m | C23: 460 | D23: 458 | E23: 2 x LOA graan | F23: vrij getoetst
A24: afstand tot afgemeerde schepen | B24: m | C24: 286 | D24: >0 | F24: voldoet
A25: LNG-ligplaatsenvelop | B25: m | C25: 400 | D25: 400 | E25: tekenbrief | F25: dolphins indicatief
A26: LNG-envelop tot draaikom | B26: m | C26: 561 | D26: >0 | F26: vrij; QRA volgt
A27: LNG-tanks tot containerterrein | B27: m | C27: 296 | F27: QRA volgt
A28: LNG-zone (tanks + hervergassing) | B28: ha | C28: 31.9 | E28: Invoer D51-D52 | F28: 3 tanks + optie 4e
A29: Centrale + utilities (reservering) | B29: ha | C29: 43.5 | E29: geen vast oppervlak | F29: reservering
A30: STS-kranen F1 / F2 / F3 | B30: st | C30: 6 / 12 / 20 | D30: 6 / 12 / 20 | E30: Containers D19-F19 | F30: gelijk
A31: TEU-grondslots stackzone F3 (28 m2/slot) | B31: slots | C31: 40558 | D31: 40444 | E31: Containers F25 | F31: voldoet
A32: Stackzone bruto | B32: ha | C32: 113.6 | D32: 113.2 | E32: Containers F26 | F32: voldoet
A33: Graansilo's 8 x D 30 m x 40 m | B33: t | C33: 169646 | D33: 154100 | E33: Overige terminals F9 | F33: voldoet
A34: RoRo-parkeercapaciteit | B34: auto's | C34: 9698 | D34: 7479 | E34: Overige terminals F15 | F34: voldoet
A35: Centrale STEG-eenheden | B35: MW | C35: 2260 | D35: 2256 | E35: Overige terminals F30 | F35: rekenvoorbeeld
A36: Havendiensten / sleepboten | B36: ha | C36: 43 | F36: reservering
A37: Vrije breedte hoofdbekken met graanschip aan de kade | B37: m | C37: 334 | D37: 220 | F37: voldoet
A38: Binnenbekken gebaggerd fase 1 | B38: m2 | C38: 1324523
A39: Binnenbekken gebaggerd fase 2 (cumulatief) | B39: m2 | C39: 1461326
A40: Binnenbekken gebaggerd fase 3 (cumulatief) | B40: m2 | C40: 1598128
...
